[2025-06-26T20:38:55.430+0000] {taskinstance.py:1956} INFO - Dependencies all met for dep_context=non-requeueable deps ti=<TaskInstance: cards_etl.etl_cards_task manual__2025-06-26T20:38:28.791923+00:00 [queued]>
[2025-06-26T20:38:55.452+0000] {taskinstance.py:1956} INFO - Dependencies all met for dep_context=requeueable deps ti=<TaskInstance: cards_etl.etl_cards_task manual__2025-06-26T20:38:28.791923+00:00 [queued]>
[2025-06-26T20:38:55.453+0000] {taskinstance.py:2170} INFO - Starting attempt 2 of 2
[2025-06-26T20:38:55.545+0000] {taskinstance.py:2191} INFO - Executing <Task(PythonOperator): etl_cards_task> on 2025-06-26 20:38:28.791923+00:00
[2025-06-26T20:38:55.558+0000] {standard_task_runner.py:60} INFO - Started process 6823 to run task
[2025-06-26T20:38:55.576+0000] {standard_task_runner.py:87} INFO - Running: ['***', 'tasks', 'run', 'cards_etl', 'etl_cards_task', 'manual__2025-06-26T20:38:28.791923+00:00', '--job-id', '74', '--raw', '--subdir', 'DAGS_FOLDER/etl_cards_dag.py', '--cfg-path', '/tmp/tmpp72w38z0']
[2025-06-26T20:38:55.594+0000] {standard_task_runner.py:88} INFO - Job 74: Subtask etl_cards_task
[2025-06-26T20:38:55.689+0000] {task_command.py:423} INFO - Running <TaskInstance: cards_etl.etl_cards_task manual__2025-06-26T20:38:28.791923+00:00 [running]> on host 65da94c758f2
[2025-06-26T20:38:56.217+0000] {taskinstance.py:2480} INFO - Exporting env vars: AIRFLOW_CTX_DAG_OWNER='jimmy' AIRFLOW_CTX_DAG_ID='cards_etl' AIRFLOW_CTX_TASK_ID='etl_cards_task' AIRFLOW_CTX_EXECUTION_DATE='2025-06-26T20:38:28.791923+00:00' AIRFLOW_CTX_TRY_NUMBER='2' AIRFLOW_CTX_DAG_RUN_ID='manual__2025-06-26T20:38:28.791923+00:00'
[2025-06-26T20:38:56.220+0000] {etl_cards_dag.py:22} INFO - Starting ETL for cards
[2025-06-26T20:38:56.291+0000] {ETL_dim_card.py:21} INFO - âœ… Extracted cards_data.csv with 6146 records
[2025-06-26T20:38:56.292+0000] {ETL_dim_card.py:36} INFO - Starting transformation of CARDS data.
[2025-06-26T20:38:56.352+0000] {ETL_dim_card.py:63} ERROR - An error occurred while transforming CARDS data: name 'datetime' is not defined
[2025-06-26T20:38:56.354+0000] {taskinstance.py:2698} ERROR - Task failed with exception
Traceback (most recent call last):
  File "/home/airflow/.local/lib/python3.8/site-packages/airflow/models/taskinstance.py", line 433, in _execute_task
    result = execute_callable(context=context, **execute_callable_kwargs)
  File "/home/airflow/.local/lib/python3.8/site-packages/airflow/operators/python.py", line 199, in execute
    return_value = self.execute_callable()
  File "/home/airflow/.local/lib/python3.8/site-packages/airflow/operators/python.py", line 216, in execute_callable
    return self.python_callable(*self.op_args, **self.op_kwargs)
  File "/opt/airflow/dags/etl_cards_dag.py", line 24, in my_etl_task
    cards_df_clean = etl_dim_card.cards_transform(cards_df)
  File "/opt/airflow/ETL/ETL_dim_card.py", line 57, in cards_transform
    df_cleaned['load_timestamp'] = datetime.now()
NameError: name 'datetime' is not defined
[2025-06-26T20:38:56.386+0000] {taskinstance.py:1138} INFO - Marking task as FAILED. dag_id=cards_etl, task_id=etl_cards_task, execution_date=20250626T203828, start_date=20250626T203855, end_date=20250626T203856
[2025-06-26T20:38:56.474+0000] {standard_task_runner.py:107} ERROR - Failed to execute job 74 for task etl_cards_task (name 'datetime' is not defined; 6823)
[2025-06-26T20:38:56.526+0000] {local_task_job_runner.py:234} INFO - Task exited with return code 1
[2025-06-26T20:38:56.559+0000] {taskinstance.py:3280} INFO - 0 downstream tasks scheduled from follow-on schedule check
