[2025-06-18T12:39:10.754+0000] {scheduler_job_runner.py:1586} WARNING - Marking task instance <TaskInstance: cards_etl.etl_cards_task manual__2025-06-18T12:11:46.287270+00:00 [queued]> stuck in queued as failed. If the task instance has available retries, it will be retried.
[2025-06-18T12:39:10.991+0000] {scheduler_job_runner.py:781} ERROR - Executor reports task instance <TaskInstance: cards_etl.etl_cards_task manual__2025-06-18T12:11:46.287270+00:00 [queued]> finished (failed) although the task says it's queued. (Info: None) Was the task killed externally?
