[2025-06-19T12:17:15.523+0000] {taskinstance.py:1956} INFO - Dependencies all met for dep_context=non-requeueable deps ti=<TaskInstance: cards_etl.etl_cards_task manual__2025-06-19T12:17:12.377767+00:00 [queued]>
[2025-06-19T12:17:15.547+0000] {taskinstance.py:1956} INFO - Dependencies all met for dep_context=requeueable deps ti=<TaskInstance: cards_etl.etl_cards_task manual__2025-06-19T12:17:12.377767+00:00 [queued]>
[2025-06-19T12:17:15.549+0000] {taskinstance.py:2170} INFO - Starting attempt 1 of 2
[2025-06-19T12:17:15.586+0000] {taskinstance.py:2191} INFO - Executing <Task(PythonOperator): etl_cards_task> on 2025-06-19 12:17:12.377767+00:00
[2025-06-19T12:17:15.608+0000] {standard_task_runner.py:60} INFO - Started process 221 to run task
[2025-06-19T12:17:15.617+0000] {standard_task_runner.py:87} INFO - Running: ['***', 'tasks', 'run', 'cards_etl', 'etl_cards_task', 'manual__2025-06-19T12:17:12.377767+00:00', '--job-id', '19', '--raw', '--subdir', 'DAGS_FOLDER/etl_cards_dag.py', '--cfg-path', '/tmp/tmph1l0awjh']
[2025-06-19T12:17:15.623+0000] {standard_task_runner.py:88} INFO - Job 19: Subtask etl_cards_task
[2025-06-19T12:17:15.760+0000] {task_command.py:423} INFO - Running <TaskInstance: cards_etl.etl_cards_task manual__2025-06-19T12:17:12.377767+00:00 [running]> on host 9aab1b97046e
[2025-06-19T12:17:16.630+0000] {taskinstance.py:2480} INFO - Exporting env vars: AIRFLOW_CTX_DAG_OWNER='jimmy' AIRFLOW_CTX_DAG_ID='cards_etl' AIRFLOW_CTX_TASK_ID='etl_cards_task' AIRFLOW_CTX_EXECUTION_DATE='2025-06-19T12:17:12.377767+00:00' AIRFLOW_CTX_TRY_NUMBER='1' AIRFLOW_CTX_DAG_RUN_ID='manual__2025-06-19T12:17:12.377767+00:00'
[2025-06-19T12:17:16.633+0000] {etl_cards_dag.py:21} INFO - Starting ETL for cards
[2025-06-19T12:17:16.707+0000] {extract_data.py:22} INFO - âœ… Extracted cards_data.csv with 6146 records
[2025-06-19T12:17:16.750+0000] {transform_cards.py:71} INFO - Removed columns ['client_id', 'card_number', 'cvv'] from CARDS data.
[2025-06-19T12:17:16.773+0000] {transform_cards.py:93} ERROR - An error occurred while setting data types in CARDS data: 'expiry_date'
[2025-06-19T12:17:16.775+0000] {taskinstance.py:2698} ERROR - Task failed with exception
Traceback (most recent call last):
  File "/home/airflow/.local/lib/python3.8/site-packages/pandas/core/indexes/base.py", line 3653, in get_loc
    return self._engine.get_loc(casted_key)
  File "pandas/_libs/index.pyx", line 147, in pandas._libs.index.IndexEngine.get_loc
  File "pandas/_libs/index.pyx", line 176, in pandas._libs.index.IndexEngine.get_loc
  File "pandas/_libs/hashtable_class_helper.pxi", line 7080, in pandas._libs.hashtable.PyObjectHashTable.get_item
  File "pandas/_libs/hashtable_class_helper.pxi", line 7088, in pandas._libs.hashtable.PyObjectHashTable.get_item
KeyError: 'expiry_date'

The above exception was the direct cause of the following exception:

Traceback (most recent call last):
  File "/home/airflow/.local/lib/python3.8/site-packages/airflow/models/taskinstance.py", line 433, in _execute_task
    result = execute_callable(context=context, **execute_callable_kwargs)
  File "/home/airflow/.local/lib/python3.8/site-packages/airflow/operators/python.py", line 199, in execute
    return_value = self.execute_callable()
  File "/home/airflow/.local/lib/python3.8/site-packages/airflow/operators/python.py", line 216, in execute_callable
    return self.python_callable(*self.op_args, **self.op_kwargs)
  File "/opt/airflow/dags/etl_cards_dag.py", line 24, in my_etl_task
    cards_df_clean2 = transform.cards_set_data_types(cards_df_clean1)
  File "/opt/airflow/ETL/transform_cards.py", line 88, in cards_set_data_types
    df['expiry_date'] = pd.to_datetime(df['expiry_date'], errors='coerce')
  File "/home/airflow/.local/lib/python3.8/site-packages/pandas/core/frame.py", line 3761, in __getitem__
    indexer = self.columns.get_loc(key)
  File "/home/airflow/.local/lib/python3.8/site-packages/pandas/core/indexes/base.py", line 3655, in get_loc
    raise KeyError(key) from err
KeyError: 'expiry_date'
[2025-06-19T12:17:16.895+0000] {taskinstance.py:1138} INFO - Marking task as UP_FOR_RETRY. dag_id=cards_etl, task_id=etl_cards_task, execution_date=20250619T121712, start_date=20250619T121715, end_date=20250619T121716
[2025-06-19T12:17:16.928+0000] {standard_task_runner.py:107} ERROR - Failed to execute job 19 for task etl_cards_task ('expiry_date'; 221)
[2025-06-19T12:17:16.999+0000] {local_task_job_runner.py:234} INFO - Task exited with return code 1
[2025-06-19T12:17:17.042+0000] {taskinstance.py:3280} INFO - 0 downstream tasks scheduled from follow-on schedule check
