[2025-06-22T16:05:39.317+0000] {processor.py:161} INFO - Started process (PID=1953) to work on /opt/airflow/dags/etl_cards_dag.py
[2025-06-22T16:05:39.330+0000] {processor.py:830} INFO - Processing file /opt/airflow/dags/etl_cards_dag.py for tasks to queue
[2025-06-22T16:05:39.387+0000] {logging_mixin.py:188} INFO - [2025-06-22T16:05:39.376+0000] {dagbag.py:538} INFO - Filling up the DagBag from /opt/airflow/dags/etl_cards_dag.py
[2025-06-22T16:05:50.494+0000] {logging_mixin.py:188} INFO - [2025-06-22T16:05:50.434+0000] {dagbag.py:348} ERROR - Failed to import: /opt/airflow/dags/etl_cards_dag.py
Traceback (most recent call last):
  File "/home/airflow/.local/lib/python3.8/site-packages/airflow/models/dagbag.py", line 344, in parse
    loader.exec_module(new_module)
  File "<frozen importlib._bootstrap_external>", line 843, in exec_module
  File "<frozen importlib._bootstrap>", line 219, in _call_with_frames_removed
  File "/opt/airflow/dags/etl_cards_dag.py", line 13, in <module>
    import ETL.extract_data as extract
  File "/opt/airflow/ETL/extract_data.py", line 5, in <module>
    import ETL.config as config
  File "/opt/airflow/ETL/config.py", line 8
    CARDS_FILE_LOCAL = os.path.join(DATA_DIR, "cards_data.csv") use to test in local
                                                                ^
SyntaxError: invalid syntax
[2025-06-22T16:05:50.519+0000] {processor.py:842} WARNING - No viable dags retrieved from /opt/airflow/dags/etl_cards_dag.py
[2025-06-22T16:05:50.627+0000] {processor.py:183} INFO - Processing /opt/airflow/dags/etl_cards_dag.py took 11.447 seconds
[2025-06-22T16:06:20.947+0000] {processor.py:161} INFO - Started process (PID=1967) to work on /opt/airflow/dags/etl_cards_dag.py
[2025-06-22T16:06:20.950+0000] {processor.py:830} INFO - Processing file /opt/airflow/dags/etl_cards_dag.py for tasks to queue
[2025-06-22T16:06:20.952+0000] {logging_mixin.py:188} INFO - [2025-06-22T16:06:20.951+0000] {dagbag.py:538} INFO - Filling up the DagBag from /opt/airflow/dags/etl_cards_dag.py
[2025-06-22T16:06:22.254+0000] {logging_mixin.py:188} INFO - [2025-06-22T16:06:22.235+0000] {dagbag.py:348} ERROR - Failed to import: /opt/airflow/dags/etl_cards_dag.py
Traceback (most recent call last):
  File "/home/airflow/.local/lib/python3.8/site-packages/airflow/models/dagbag.py", line 344, in parse
    loader.exec_module(new_module)
  File "<frozen importlib._bootstrap_external>", line 843, in exec_module
  File "<frozen importlib._bootstrap>", line 219, in _call_with_frames_removed
  File "/opt/airflow/dags/etl_cards_dag.py", line 13, in <module>
    import ETL.extract_data as extract
  File "/opt/airflow/ETL/extract_data.py", line 5, in <module>
    import ETL.config as config
  File "/opt/airflow/ETL/config.py", line 8
    CARDS_FILE_LOCAL = os.path.join(DATA_DIR, "cards_data.csv") use to test in local
                                                                ^
SyntaxError: invalid syntax
[2025-06-22T16:06:22.261+0000] {processor.py:842} WARNING - No viable dags retrieved from /opt/airflow/dags/etl_cards_dag.py
[2025-06-22T16:06:22.302+0000] {processor.py:183} INFO - Processing /opt/airflow/dags/etl_cards_dag.py took 1.363 seconds
[2025-06-22T16:06:52.474+0000] {processor.py:161} INFO - Started process (PID=1975) to work on /opt/airflow/dags/etl_cards_dag.py
[2025-06-22T16:06:52.477+0000] {processor.py:830} INFO - Processing file /opt/airflow/dags/etl_cards_dag.py for tasks to queue
[2025-06-22T16:06:52.480+0000] {logging_mixin.py:188} INFO - [2025-06-22T16:06:52.479+0000] {dagbag.py:538} INFO - Filling up the DagBag from /opt/airflow/dags/etl_cards_dag.py
[2025-06-22T16:06:53.433+0000] {logging_mixin.py:188} INFO - [2025-06-22T16:06:53.411+0000] {dagbag.py:348} ERROR - Failed to import: /opt/airflow/dags/etl_cards_dag.py
Traceback (most recent call last):
  File "/home/airflow/.local/lib/python3.8/site-packages/airflow/models/dagbag.py", line 344, in parse
    loader.exec_module(new_module)
  File "<frozen importlib._bootstrap_external>", line 843, in exec_module
  File "<frozen importlib._bootstrap>", line 219, in _call_with_frames_removed
  File "/opt/airflow/dags/etl_cards_dag.py", line 13, in <module>
    import ETL.extract_data as extract
  File "/opt/airflow/ETL/extract_data.py", line 5, in <module>
    import ETL.config as config
  File "/opt/airflow/ETL/config.py", line 8
    CARDS_FILE_LOCAL = os.path.join(DATA_DIR, "cards_data.csv") use to test in local
                                                                ^
SyntaxError: invalid syntax
[2025-06-22T16:06:53.439+0000] {processor.py:842} WARNING - No viable dags retrieved from /opt/airflow/dags/etl_cards_dag.py
[2025-06-22T16:06:53.491+0000] {processor.py:183} INFO - Processing /opt/airflow/dags/etl_cards_dag.py took 1.023 seconds
[2025-06-22T16:07:23.881+0000] {processor.py:161} INFO - Started process (PID=1983) to work on /opt/airflow/dags/etl_cards_dag.py
[2025-06-22T16:07:23.884+0000] {processor.py:830} INFO - Processing file /opt/airflow/dags/etl_cards_dag.py for tasks to queue
[2025-06-22T16:07:23.886+0000] {logging_mixin.py:188} INFO - [2025-06-22T16:07:23.886+0000] {dagbag.py:538} INFO - Filling up the DagBag from /opt/airflow/dags/etl_cards_dag.py
[2025-06-22T16:07:25.017+0000] {logging_mixin.py:188} INFO - [2025-06-22T16:07:24.998+0000] {dagbag.py:348} ERROR - Failed to import: /opt/airflow/dags/etl_cards_dag.py
Traceback (most recent call last):
  File "/home/airflow/.local/lib/python3.8/site-packages/airflow/models/dagbag.py", line 344, in parse
    loader.exec_module(new_module)
  File "<frozen importlib._bootstrap_external>", line 843, in exec_module
  File "<frozen importlib._bootstrap>", line 219, in _call_with_frames_removed
  File "/opt/airflow/dags/etl_cards_dag.py", line 13, in <module>
    import ETL.extract_data as extract
  File "/opt/airflow/ETL/extract_data.py", line 5, in <module>
    import ETL.config as config
  File "/opt/airflow/ETL/config.py", line 8
    CARDS_FILE_LOCAL = os.path.join(DATA_DIR, "cards_data.csv") use to test in local
                                                                ^
SyntaxError: invalid syntax
[2025-06-22T16:07:25.024+0000] {processor.py:842} WARNING - No viable dags retrieved from /opt/airflow/dags/etl_cards_dag.py
[2025-06-22T16:07:25.068+0000] {processor.py:183} INFO - Processing /opt/airflow/dags/etl_cards_dag.py took 1.193 seconds
[2025-06-22T16:07:55.277+0000] {processor.py:161} INFO - Started process (PID=1991) to work on /opt/airflow/dags/etl_cards_dag.py
[2025-06-22T16:07:55.280+0000] {processor.py:830} INFO - Processing file /opt/airflow/dags/etl_cards_dag.py for tasks to queue
[2025-06-22T16:07:55.282+0000] {logging_mixin.py:188} INFO - [2025-06-22T16:07:55.282+0000] {dagbag.py:538} INFO - Filling up the DagBag from /opt/airflow/dags/etl_cards_dag.py
[2025-06-22T16:07:56.560+0000] {logging_mixin.py:188} INFO - [2025-06-22T16:07:56.535+0000] {dagbag.py:348} ERROR - Failed to import: /opt/airflow/dags/etl_cards_dag.py
Traceback (most recent call last):
  File "/home/airflow/.local/lib/python3.8/site-packages/airflow/models/dagbag.py", line 344, in parse
    loader.exec_module(new_module)
  File "<frozen importlib._bootstrap_external>", line 843, in exec_module
  File "<frozen importlib._bootstrap>", line 219, in _call_with_frames_removed
  File "/opt/airflow/dags/etl_cards_dag.py", line 13, in <module>
    import ETL.extract_data as extract
  File "/opt/airflow/ETL/extract_data.py", line 5, in <module>
    import ETL.config as config
  File "/opt/airflow/ETL/config.py", line 8
    CARDS_FILE_LOCAL = os.path.join(DATA_DIR, "cards_data.csv") use to test in local
                                                                ^
SyntaxError: invalid syntax
[2025-06-22T16:07:56.568+0000] {processor.py:842} WARNING - No viable dags retrieved from /opt/airflow/dags/etl_cards_dag.py
[2025-06-22T16:07:56.617+0000] {processor.py:183} INFO - Processing /opt/airflow/dags/etl_cards_dag.py took 1.349 seconds
[2025-06-22T16:08:27.001+0000] {processor.py:161} INFO - Started process (PID=2000) to work on /opt/airflow/dags/etl_cards_dag.py
[2025-06-22T16:08:27.006+0000] {processor.py:830} INFO - Processing file /opt/airflow/dags/etl_cards_dag.py for tasks to queue
[2025-06-22T16:08:27.009+0000] {logging_mixin.py:188} INFO - [2025-06-22T16:08:27.008+0000] {dagbag.py:538} INFO - Filling up the DagBag from /opt/airflow/dags/etl_cards_dag.py
[2025-06-22T16:08:28.193+0000] {logging_mixin.py:188} INFO - [2025-06-22T16:08:28.170+0000] {dagbag.py:348} ERROR - Failed to import: /opt/airflow/dags/etl_cards_dag.py
Traceback (most recent call last):
  File "/home/airflow/.local/lib/python3.8/site-packages/airflow/models/dagbag.py", line 344, in parse
    loader.exec_module(new_module)
  File "<frozen importlib._bootstrap_external>", line 843, in exec_module
  File "<frozen importlib._bootstrap>", line 219, in _call_with_frames_removed
  File "/opt/airflow/dags/etl_cards_dag.py", line 13, in <module>
    import ETL.extract_data as extract
  File "/opt/airflow/ETL/extract_data.py", line 5, in <module>
    import ETL.config as config
  File "/opt/airflow/ETL/config.py", line 8
    CARDS_FILE_LOCAL = os.path.join(DATA_DIR, "cards_data.csv") use to test in local
                                                                ^
SyntaxError: invalid syntax
[2025-06-22T16:08:28.201+0000] {processor.py:842} WARNING - No viable dags retrieved from /opt/airflow/dags/etl_cards_dag.py
[2025-06-22T16:08:28.243+0000] {processor.py:183} INFO - Processing /opt/airflow/dags/etl_cards_dag.py took 1.257 seconds
[2025-06-22T16:08:58.573+0000] {processor.py:161} INFO - Started process (PID=2009) to work on /opt/airflow/dags/etl_cards_dag.py
[2025-06-22T16:08:58.576+0000] {processor.py:830} INFO - Processing file /opt/airflow/dags/etl_cards_dag.py for tasks to queue
[2025-06-22T16:08:58.579+0000] {logging_mixin.py:188} INFO - [2025-06-22T16:08:58.579+0000] {dagbag.py:538} INFO - Filling up the DagBag from /opt/airflow/dags/etl_cards_dag.py
[2025-06-22T16:09:00.005+0000] {logging_mixin.py:188} INFO - [2025-06-22T16:08:59.983+0000] {dagbag.py:348} ERROR - Failed to import: /opt/airflow/dags/etl_cards_dag.py
Traceback (most recent call last):
  File "/home/airflow/.local/lib/python3.8/site-packages/airflow/models/dagbag.py", line 344, in parse
    loader.exec_module(new_module)
  File "<frozen importlib._bootstrap_external>", line 843, in exec_module
  File "<frozen importlib._bootstrap>", line 219, in _call_with_frames_removed
  File "/opt/airflow/dags/etl_cards_dag.py", line 13, in <module>
    import ETL.extract_data as extract
  File "/opt/airflow/ETL/extract_data.py", line 5, in <module>
    import ETL.config as config
  File "/opt/airflow/ETL/config.py", line 8
    CARDS_FILE_LOCAL = os.path.join(DATA_DIR, "cards_data.csv") use to test in local
                                                                ^
SyntaxError: invalid syntax
[2025-06-22T16:09:00.014+0000] {processor.py:842} WARNING - No viable dags retrieved from /opt/airflow/dags/etl_cards_dag.py
[2025-06-22T16:09:00.059+0000] {processor.py:183} INFO - Processing /opt/airflow/dags/etl_cards_dag.py took 1.492 seconds
[2025-06-22T16:09:30.555+0000] {processor.py:161} INFO - Started process (PID=2017) to work on /opt/airflow/dags/etl_cards_dag.py
[2025-06-22T16:09:30.558+0000] {processor.py:830} INFO - Processing file /opt/airflow/dags/etl_cards_dag.py for tasks to queue
[2025-06-22T16:09:30.561+0000] {logging_mixin.py:188} INFO - [2025-06-22T16:09:30.560+0000] {dagbag.py:538} INFO - Filling up the DagBag from /opt/airflow/dags/etl_cards_dag.py
[2025-06-22T16:09:31.729+0000] {logging_mixin.py:188} INFO - [2025-06-22T16:09:31.706+0000] {dagbag.py:348} ERROR - Failed to import: /opt/airflow/dags/etl_cards_dag.py
Traceback (most recent call last):
  File "/home/airflow/.local/lib/python3.8/site-packages/airflow/models/dagbag.py", line 344, in parse
    loader.exec_module(new_module)
  File "<frozen importlib._bootstrap_external>", line 843, in exec_module
  File "<frozen importlib._bootstrap>", line 219, in _call_with_frames_removed
  File "/opt/airflow/dags/etl_cards_dag.py", line 13, in <module>
    import ETL.extract_data as extract
  File "/opt/airflow/ETL/extract_data.py", line 5, in <module>
    import ETL.config as config
  File "/opt/airflow/ETL/config.py", line 8
    CARDS_FILE_LOCAL = os.path.join(DATA_DIR, "cards_data.csv") use to test in local
                                                                ^
SyntaxError: invalid syntax
[2025-06-22T16:09:31.737+0000] {processor.py:842} WARNING - No viable dags retrieved from /opt/airflow/dags/etl_cards_dag.py
[2025-06-22T16:09:31.780+0000] {processor.py:183} INFO - Processing /opt/airflow/dags/etl_cards_dag.py took 1.233 seconds
[2025-06-22T16:10:01.970+0000] {processor.py:161} INFO - Started process (PID=2025) to work on /opt/airflow/dags/etl_cards_dag.py
[2025-06-22T16:10:01.974+0000] {processor.py:830} INFO - Processing file /opt/airflow/dags/etl_cards_dag.py for tasks to queue
[2025-06-22T16:10:01.977+0000] {logging_mixin.py:188} INFO - [2025-06-22T16:10:01.977+0000] {dagbag.py:538} INFO - Filling up the DagBag from /opt/airflow/dags/etl_cards_dag.py
[2025-06-22T16:10:02.976+0000] {logging_mixin.py:188} INFO - [2025-06-22T16:10:02.960+0000] {dagbag.py:348} ERROR - Failed to import: /opt/airflow/dags/etl_cards_dag.py
Traceback (most recent call last):
  File "/home/airflow/.local/lib/python3.8/site-packages/airflow/models/dagbag.py", line 344, in parse
    loader.exec_module(new_module)
  File "<frozen importlib._bootstrap_external>", line 843, in exec_module
  File "<frozen importlib._bootstrap>", line 219, in _call_with_frames_removed
  File "/opt/airflow/dags/etl_cards_dag.py", line 13, in <module>
    import ETL.extract_data as extract
  File "/opt/airflow/ETL/extract_data.py", line 5, in <module>
    import ETL.config as config
  File "/opt/airflow/ETL/config.py", line 8
    CARDS_FILE_LOCAL = os.path.join(DATA_DIR, "cards_data.csv") use to test in local
                                                                ^
SyntaxError: invalid syntax
[2025-06-22T16:10:02.981+0000] {processor.py:842} WARNING - No viable dags retrieved from /opt/airflow/dags/etl_cards_dag.py
[2025-06-22T16:10:03.018+0000] {processor.py:183} INFO - Processing /opt/airflow/dags/etl_cards_dag.py took 1.059 seconds
[2025-06-22T16:10:33.423+0000] {processor.py:161} INFO - Started process (PID=2034) to work on /opt/airflow/dags/etl_cards_dag.py
[2025-06-22T16:10:33.426+0000] {processor.py:830} INFO - Processing file /opt/airflow/dags/etl_cards_dag.py for tasks to queue
[2025-06-22T16:10:33.429+0000] {logging_mixin.py:188} INFO - [2025-06-22T16:10:33.428+0000] {dagbag.py:538} INFO - Filling up the DagBag from /opt/airflow/dags/etl_cards_dag.py
[2025-06-22T16:10:34.515+0000] {logging_mixin.py:188} INFO - [2025-06-22T16:10:34.496+0000] {dagbag.py:348} ERROR - Failed to import: /opt/airflow/dags/etl_cards_dag.py
Traceback (most recent call last):
  File "/home/airflow/.local/lib/python3.8/site-packages/airflow/models/dagbag.py", line 344, in parse
    loader.exec_module(new_module)
  File "<frozen importlib._bootstrap_external>", line 843, in exec_module
  File "<frozen importlib._bootstrap>", line 219, in _call_with_frames_removed
  File "/opt/airflow/dags/etl_cards_dag.py", line 13, in <module>
    import ETL.extract_data as extract
  File "/opt/airflow/ETL/extract_data.py", line 5, in <module>
    import ETL.config as config
  File "/opt/airflow/ETL/config.py", line 8
    CARDS_FILE_LOCAL = os.path.join(DATA_DIR, "cards_data.csv") use to test in local
                                                                ^
SyntaxError: invalid syntax
[2025-06-22T16:10:34.522+0000] {processor.py:842} WARNING - No viable dags retrieved from /opt/airflow/dags/etl_cards_dag.py
[2025-06-22T16:10:34.568+0000] {processor.py:183} INFO - Processing /opt/airflow/dags/etl_cards_dag.py took 1.155 seconds
[2025-06-22T16:11:05.021+0000] {processor.py:161} INFO - Started process (PID=2042) to work on /opt/airflow/dags/etl_cards_dag.py
[2025-06-22T16:11:05.024+0000] {processor.py:830} INFO - Processing file /opt/airflow/dags/etl_cards_dag.py for tasks to queue
[2025-06-22T16:11:05.030+0000] {logging_mixin.py:188} INFO - [2025-06-22T16:11:05.028+0000] {dagbag.py:538} INFO - Filling up the DagBag from /opt/airflow/dags/etl_cards_dag.py
[2025-06-22T16:11:06.124+0000] {logging_mixin.py:188} INFO - [2025-06-22T16:11:06.109+0000] {dagbag.py:348} ERROR - Failed to import: /opt/airflow/dags/etl_cards_dag.py
Traceback (most recent call last):
  File "/home/airflow/.local/lib/python3.8/site-packages/airflow/models/dagbag.py", line 344, in parse
    loader.exec_module(new_module)
  File "<frozen importlib._bootstrap_external>", line 843, in exec_module
  File "<frozen importlib._bootstrap>", line 219, in _call_with_frames_removed
  File "/opt/airflow/dags/etl_cards_dag.py", line 13, in <module>
    import ETL.extract_data as extract
  File "/opt/airflow/ETL/extract_data.py", line 5, in <module>
    import ETL.config as config
  File "/opt/airflow/ETL/config.py", line 8
    CARDS_FILE_LOCAL = os.path.join(DATA_DIR, "cards_data.csv") use to test in local
                                                                ^
SyntaxError: invalid syntax
[2025-06-22T16:11:06.128+0000] {processor.py:842} WARNING - No viable dags retrieved from /opt/airflow/dags/etl_cards_dag.py
[2025-06-22T16:11:06.167+0000] {processor.py:183} INFO - Processing /opt/airflow/dags/etl_cards_dag.py took 1.152 seconds
[2025-06-22T16:11:36.424+0000] {processor.py:161} INFO - Started process (PID=2050) to work on /opt/airflow/dags/etl_cards_dag.py
[2025-06-22T16:11:36.427+0000] {processor.py:830} INFO - Processing file /opt/airflow/dags/etl_cards_dag.py for tasks to queue
[2025-06-22T16:11:36.430+0000] {logging_mixin.py:188} INFO - [2025-06-22T16:11:36.429+0000] {dagbag.py:538} INFO - Filling up the DagBag from /opt/airflow/dags/etl_cards_dag.py
[2025-06-22T16:11:37.589+0000] {logging_mixin.py:188} INFO - [2025-06-22T16:11:37.570+0000] {dagbag.py:348} ERROR - Failed to import: /opt/airflow/dags/etl_cards_dag.py
Traceback (most recent call last):
  File "/home/airflow/.local/lib/python3.8/site-packages/airflow/models/dagbag.py", line 344, in parse
    loader.exec_module(new_module)
  File "<frozen importlib._bootstrap_external>", line 843, in exec_module
  File "<frozen importlib._bootstrap>", line 219, in _call_with_frames_removed
  File "/opt/airflow/dags/etl_cards_dag.py", line 13, in <module>
    import ETL.extract_data as extract
  File "/opt/airflow/ETL/extract_data.py", line 5, in <module>
    import ETL.config as config
  File "/opt/airflow/ETL/config.py", line 8
    CARDS_FILE_LOCAL = os.path.join(DATA_DIR, "cards_data.csv") use to test in local
                                                                ^
SyntaxError: invalid syntax
[2025-06-22T16:11:37.597+0000] {processor.py:842} WARNING - No viable dags retrieved from /opt/airflow/dags/etl_cards_dag.py
[2025-06-22T16:11:37.648+0000] {processor.py:183} INFO - Processing /opt/airflow/dags/etl_cards_dag.py took 1.231 seconds
[2025-06-22T16:12:07.944+0000] {processor.py:161} INFO - Started process (PID=2058) to work on /opt/airflow/dags/etl_cards_dag.py
[2025-06-22T16:12:07.947+0000] {processor.py:830} INFO - Processing file /opt/airflow/dags/etl_cards_dag.py for tasks to queue
[2025-06-22T16:12:07.949+0000] {logging_mixin.py:188} INFO - [2025-06-22T16:12:07.948+0000] {dagbag.py:538} INFO - Filling up the DagBag from /opt/airflow/dags/etl_cards_dag.py
[2025-06-22T16:12:09.155+0000] {logging_mixin.py:188} INFO - [2025-06-22T16:12:09.137+0000] {dagbag.py:348} ERROR - Failed to import: /opt/airflow/dags/etl_cards_dag.py
Traceback (most recent call last):
  File "/home/airflow/.local/lib/python3.8/site-packages/airflow/models/dagbag.py", line 344, in parse
    loader.exec_module(new_module)
  File "<frozen importlib._bootstrap_external>", line 843, in exec_module
  File "<frozen importlib._bootstrap>", line 219, in _call_with_frames_removed
  File "/opt/airflow/dags/etl_cards_dag.py", line 13, in <module>
    import ETL.extract_data as extract
  File "/opt/airflow/ETL/extract_data.py", line 5, in <module>
    import ETL.config as config
  File "/opt/airflow/ETL/config.py", line 8
    CARDS_FILE_LOCAL = os.path.join(DATA_DIR, "cards_data.csv") use to test in local
                                                                ^
SyntaxError: invalid syntax
[2025-06-22T16:12:09.161+0000] {processor.py:842} WARNING - No viable dags retrieved from /opt/airflow/dags/etl_cards_dag.py
[2025-06-22T16:12:09.201+0000] {processor.py:183} INFO - Processing /opt/airflow/dags/etl_cards_dag.py took 1.262 seconds
[2025-06-22T16:12:39.394+0000] {processor.py:161} INFO - Started process (PID=2066) to work on /opt/airflow/dags/etl_cards_dag.py
[2025-06-22T16:12:39.398+0000] {processor.py:830} INFO - Processing file /opt/airflow/dags/etl_cards_dag.py for tasks to queue
[2025-06-22T16:12:39.401+0000] {logging_mixin.py:188} INFO - [2025-06-22T16:12:39.400+0000] {dagbag.py:538} INFO - Filling up the DagBag from /opt/airflow/dags/etl_cards_dag.py
[2025-06-22T16:12:40.704+0000] {logging_mixin.py:188} INFO - [2025-06-22T16:12:40.686+0000] {dagbag.py:348} ERROR - Failed to import: /opt/airflow/dags/etl_cards_dag.py
Traceback (most recent call last):
  File "/home/airflow/.local/lib/python3.8/site-packages/airflow/models/dagbag.py", line 344, in parse
    loader.exec_module(new_module)
  File "<frozen importlib._bootstrap_external>", line 843, in exec_module
  File "<frozen importlib._bootstrap>", line 219, in _call_with_frames_removed
  File "/opt/airflow/dags/etl_cards_dag.py", line 13, in <module>
    import ETL.extract_data as extract
  File "/opt/airflow/ETL/extract_data.py", line 5, in <module>
    import ETL.config as config
  File "/opt/airflow/ETL/config.py", line 8
    CARDS_FILE_LOCAL = os.path.join(DATA_DIR, "cards_data.csv") use to test in local
                                                                ^
SyntaxError: invalid syntax
[2025-06-22T16:12:40.711+0000] {processor.py:842} WARNING - No viable dags retrieved from /opt/airflow/dags/etl_cards_dag.py
[2025-06-22T16:12:40.754+0000] {processor.py:183} INFO - Processing /opt/airflow/dags/etl_cards_dag.py took 1.367 seconds
[2025-06-22T16:13:11.017+0000] {processor.py:161} INFO - Started process (PID=2074) to work on /opt/airflow/dags/etl_cards_dag.py
[2025-06-22T16:13:11.020+0000] {processor.py:830} INFO - Processing file /opt/airflow/dags/etl_cards_dag.py for tasks to queue
[2025-06-22T16:13:11.023+0000] {logging_mixin.py:188} INFO - [2025-06-22T16:13:11.023+0000] {dagbag.py:538} INFO - Filling up the DagBag from /opt/airflow/dags/etl_cards_dag.py
[2025-06-22T16:13:12.213+0000] {logging_mixin.py:188} INFO - [2025-06-22T16:13:12.196+0000] {dagbag.py:348} ERROR - Failed to import: /opt/airflow/dags/etl_cards_dag.py
Traceback (most recent call last):
  File "/home/airflow/.local/lib/python3.8/site-packages/airflow/models/dagbag.py", line 344, in parse
    loader.exec_module(new_module)
  File "<frozen importlib._bootstrap_external>", line 843, in exec_module
  File "<frozen importlib._bootstrap>", line 219, in _call_with_frames_removed
  File "/opt/airflow/dags/etl_cards_dag.py", line 13, in <module>
    import ETL.extract_data as extract
  File "/opt/airflow/ETL/extract_data.py", line 5, in <module>
    import ETL.config as config
  File "/opt/airflow/ETL/config.py", line 8
    CARDS_FILE_LOCAL = os.path.join(DATA_DIR, "cards_data.csv") use to test in local
                                                                ^
SyntaxError: invalid syntax
[2025-06-22T16:13:12.220+0000] {processor.py:842} WARNING - No viable dags retrieved from /opt/airflow/dags/etl_cards_dag.py
[2025-06-22T16:13:12.260+0000] {processor.py:183} INFO - Processing /opt/airflow/dags/etl_cards_dag.py took 1.254 seconds
[2025-06-22T16:13:42.548+0000] {processor.py:161} INFO - Started process (PID=2082) to work on /opt/airflow/dags/etl_cards_dag.py
[2025-06-22T16:13:42.550+0000] {processor.py:830} INFO - Processing file /opt/airflow/dags/etl_cards_dag.py for tasks to queue
[2025-06-22T16:13:42.553+0000] {logging_mixin.py:188} INFO - [2025-06-22T16:13:42.552+0000] {dagbag.py:538} INFO - Filling up the DagBag from /opt/airflow/dags/etl_cards_dag.py
[2025-06-22T16:13:43.532+0000] {logging_mixin.py:188} INFO - [2025-06-22T16:13:43.517+0000] {dagbag.py:348} ERROR - Failed to import: /opt/airflow/dags/etl_cards_dag.py
Traceback (most recent call last):
  File "/home/airflow/.local/lib/python3.8/site-packages/airflow/models/dagbag.py", line 344, in parse
    loader.exec_module(new_module)
  File "<frozen importlib._bootstrap_external>", line 843, in exec_module
  File "<frozen importlib._bootstrap>", line 219, in _call_with_frames_removed
  File "/opt/airflow/dags/etl_cards_dag.py", line 13, in <module>
    import ETL.extract_data as extract
  File "/opt/airflow/ETL/extract_data.py", line 5, in <module>
    import ETL.config as config
  File "/opt/airflow/ETL/config.py", line 8
    CARDS_FILE_LOCAL = os.path.join(DATA_DIR, "cards_data.csv") use to test in local
                                                                ^
SyntaxError: invalid syntax
[2025-06-22T16:13:43.537+0000] {processor.py:842} WARNING - No viable dags retrieved from /opt/airflow/dags/etl_cards_dag.py
[2025-06-22T16:13:43.636+0000] {processor.py:183} INFO - Processing /opt/airflow/dags/etl_cards_dag.py took 1.094 seconds
[2025-06-22T16:14:13.959+0000] {processor.py:161} INFO - Started process (PID=2090) to work on /opt/airflow/dags/etl_cards_dag.py
[2025-06-22T16:14:13.961+0000] {processor.py:830} INFO - Processing file /opt/airflow/dags/etl_cards_dag.py for tasks to queue
[2025-06-22T16:14:13.964+0000] {logging_mixin.py:188} INFO - [2025-06-22T16:14:13.964+0000] {dagbag.py:538} INFO - Filling up the DagBag from /opt/airflow/dags/etl_cards_dag.py
[2025-06-22T16:14:14.902+0000] {logging_mixin.py:188} INFO - [2025-06-22T16:14:14.883+0000] {dagbag.py:348} ERROR - Failed to import: /opt/airflow/dags/etl_cards_dag.py
Traceback (most recent call last):
  File "/home/airflow/.local/lib/python3.8/site-packages/airflow/models/dagbag.py", line 344, in parse
    loader.exec_module(new_module)
  File "<frozen importlib._bootstrap_external>", line 843, in exec_module
  File "<frozen importlib._bootstrap>", line 219, in _call_with_frames_removed
  File "/opt/airflow/dags/etl_cards_dag.py", line 13, in <module>
    import ETL.extract_data as extract
  File "/opt/airflow/ETL/extract_data.py", line 5, in <module>
    import ETL.config as config
  File "/opt/airflow/ETL/config.py", line 8
    CARDS_FILE_LOCAL = os.path.join(DATA_DIR, "cards_data.csv") use to test in local
                                                                ^
SyntaxError: invalid syntax
[2025-06-22T16:14:14.908+0000] {processor.py:842} WARNING - No viable dags retrieved from /opt/airflow/dags/etl_cards_dag.py
[2025-06-22T16:14:14.951+0000] {processor.py:183} INFO - Processing /opt/airflow/dags/etl_cards_dag.py took 0.999 seconds
[2025-06-22T16:14:45.382+0000] {processor.py:161} INFO - Started process (PID=2098) to work on /opt/airflow/dags/etl_cards_dag.py
[2025-06-22T16:14:45.385+0000] {processor.py:830} INFO - Processing file /opt/airflow/dags/etl_cards_dag.py for tasks to queue
[2025-06-22T16:14:45.387+0000] {logging_mixin.py:188} INFO - [2025-06-22T16:14:45.387+0000] {dagbag.py:538} INFO - Filling up the DagBag from /opt/airflow/dags/etl_cards_dag.py
[2025-06-22T16:14:46.326+0000] {logging_mixin.py:188} INFO - [2025-06-22T16:14:46.311+0000] {dagbag.py:348} ERROR - Failed to import: /opt/airflow/dags/etl_cards_dag.py
Traceback (most recent call last):
  File "/home/airflow/.local/lib/python3.8/site-packages/airflow/models/dagbag.py", line 344, in parse
    loader.exec_module(new_module)
  File "<frozen importlib._bootstrap_external>", line 843, in exec_module
  File "<frozen importlib._bootstrap>", line 219, in _call_with_frames_removed
  File "/opt/airflow/dags/etl_cards_dag.py", line 13, in <module>
    import ETL.extract_data as extract
  File "/opt/airflow/ETL/extract_data.py", line 5, in <module>
    import ETL.config as config
  File "/opt/airflow/ETL/config.py", line 8
    CARDS_FILE_LOCAL = os.path.join(DATA_DIR, "cards_data.csv") use to test in local
                                                                ^
SyntaxError: invalid syntax
[2025-06-22T16:14:46.332+0000] {processor.py:842} WARNING - No viable dags retrieved from /opt/airflow/dags/etl_cards_dag.py
[2025-06-22T16:14:46.370+0000] {processor.py:183} INFO - Processing /opt/airflow/dags/etl_cards_dag.py took 0.994 seconds
[2025-06-22T16:15:16.849+0000] {processor.py:161} INFO - Started process (PID=2106) to work on /opt/airflow/dags/etl_cards_dag.py
[2025-06-22T16:15:16.853+0000] {processor.py:830} INFO - Processing file /opt/airflow/dags/etl_cards_dag.py for tasks to queue
[2025-06-22T16:15:16.856+0000] {logging_mixin.py:188} INFO - [2025-06-22T16:15:16.855+0000] {dagbag.py:538} INFO - Filling up the DagBag from /opt/airflow/dags/etl_cards_dag.py
[2025-06-22T16:15:18.001+0000] {logging_mixin.py:188} INFO - [2025-06-22T16:15:17.981+0000] {dagbag.py:348} ERROR - Failed to import: /opt/airflow/dags/etl_cards_dag.py
Traceback (most recent call last):
  File "/home/airflow/.local/lib/python3.8/site-packages/airflow/models/dagbag.py", line 344, in parse
    loader.exec_module(new_module)
  File "<frozen importlib._bootstrap_external>", line 843, in exec_module
  File "<frozen importlib._bootstrap>", line 219, in _call_with_frames_removed
  File "/opt/airflow/dags/etl_cards_dag.py", line 13, in <module>
    import ETL.extract_data as extract
  File "/opt/airflow/ETL/extract_data.py", line 5, in <module>
    import ETL.config as config
  File "/opt/airflow/ETL/config.py", line 8
    CARDS_FILE_LOCAL = os.path.join(DATA_DIR, "cards_data.csv") use to test in local
                                                                ^
SyntaxError: invalid syntax
[2025-06-22T16:15:18.009+0000] {processor.py:842} WARNING - No viable dags retrieved from /opt/airflow/dags/etl_cards_dag.py
[2025-06-22T16:15:18.056+0000] {processor.py:183} INFO - Processing /opt/airflow/dags/etl_cards_dag.py took 1.213 seconds
[2025-06-22T16:15:48.467+0000] {processor.py:161} INFO - Started process (PID=2114) to work on /opt/airflow/dags/etl_cards_dag.py
[2025-06-22T16:15:48.472+0000] {processor.py:830} INFO - Processing file /opt/airflow/dags/etl_cards_dag.py for tasks to queue
[2025-06-22T16:15:48.475+0000] {logging_mixin.py:188} INFO - [2025-06-22T16:15:48.474+0000] {dagbag.py:538} INFO - Filling up the DagBag from /opt/airflow/dags/etl_cards_dag.py
[2025-06-22T16:15:49.588+0000] {logging_mixin.py:188} INFO - [2025-06-22T16:15:49.572+0000] {dagbag.py:348} ERROR - Failed to import: /opt/airflow/dags/etl_cards_dag.py
Traceback (most recent call last):
  File "/home/airflow/.local/lib/python3.8/site-packages/airflow/models/dagbag.py", line 344, in parse
    loader.exec_module(new_module)
  File "<frozen importlib._bootstrap_external>", line 843, in exec_module
  File "<frozen importlib._bootstrap>", line 219, in _call_with_frames_removed
  File "/opt/airflow/dags/etl_cards_dag.py", line 13, in <module>
    import ETL.extract_data as extract
  File "/opt/airflow/ETL/extract_data.py", line 5, in <module>
    import ETL.config as config
  File "/opt/airflow/ETL/config.py", line 8
    CARDS_FILE_LOCAL = os.path.join(DATA_DIR, "cards_data.csv") use to test in local
                                                                ^
SyntaxError: invalid syntax
[2025-06-22T16:15:49.594+0000] {processor.py:842} WARNING - No viable dags retrieved from /opt/airflow/dags/etl_cards_dag.py
[2025-06-22T16:15:49.702+0000] {processor.py:183} INFO - Processing /opt/airflow/dags/etl_cards_dag.py took 1.243 seconds
[2025-06-22T16:16:19.833+0000] {processor.py:161} INFO - Started process (PID=2128) to work on /opt/airflow/dags/etl_cards_dag.py
[2025-06-22T16:16:19.836+0000] {processor.py:830} INFO - Processing file /opt/airflow/dags/etl_cards_dag.py for tasks to queue
[2025-06-22T16:16:19.842+0000] {logging_mixin.py:188} INFO - [2025-06-22T16:16:19.841+0000] {dagbag.py:538} INFO - Filling up the DagBag from /opt/airflow/dags/etl_cards_dag.py
[2025-06-22T16:16:20.890+0000] {logging_mixin.py:188} INFO - [2025-06-22T16:16:20.871+0000] {dagbag.py:348} ERROR - Failed to import: /opt/airflow/dags/etl_cards_dag.py
Traceback (most recent call last):
  File "/home/airflow/.local/lib/python3.8/site-packages/airflow/models/dagbag.py", line 344, in parse
    loader.exec_module(new_module)
  File "<frozen importlib._bootstrap_external>", line 843, in exec_module
  File "<frozen importlib._bootstrap>", line 219, in _call_with_frames_removed
  File "/opt/airflow/dags/etl_cards_dag.py", line 13, in <module>
    import ETL.extract_data as extract
  File "/opt/airflow/ETL/extract_data.py", line 5, in <module>
    import ETL.config as config
  File "/opt/airflow/ETL/config.py", line 8
    CARDS_FILE_LOCAL = os.path.join(DATA_DIR, "cards_data.csv") use to test in local
                                                                ^
SyntaxError: invalid syntax
[2025-06-22T16:16:20.897+0000] {processor.py:842} WARNING - No viable dags retrieved from /opt/airflow/dags/etl_cards_dag.py
[2025-06-22T16:16:20.940+0000] {processor.py:183} INFO - Processing /opt/airflow/dags/etl_cards_dag.py took 1.116 seconds
[2025-06-22T16:16:51.197+0000] {processor.py:161} INFO - Started process (PID=2136) to work on /opt/airflow/dags/etl_cards_dag.py
[2025-06-22T16:16:51.200+0000] {processor.py:830} INFO - Processing file /opt/airflow/dags/etl_cards_dag.py for tasks to queue
[2025-06-22T16:16:51.204+0000] {logging_mixin.py:188} INFO - [2025-06-22T16:16:51.203+0000] {dagbag.py:538} INFO - Filling up the DagBag from /opt/airflow/dags/etl_cards_dag.py
[2025-06-22T16:16:52.406+0000] {logging_mixin.py:188} INFO - [2025-06-22T16:16:52.383+0000] {dagbag.py:348} ERROR - Failed to import: /opt/airflow/dags/etl_cards_dag.py
Traceback (most recent call last):
  File "/home/airflow/.local/lib/python3.8/site-packages/airflow/models/dagbag.py", line 344, in parse
    loader.exec_module(new_module)
  File "<frozen importlib._bootstrap_external>", line 843, in exec_module
  File "<frozen importlib._bootstrap>", line 219, in _call_with_frames_removed
  File "/opt/airflow/dags/etl_cards_dag.py", line 13, in <module>
    import ETL.extract_data as extract
  File "/opt/airflow/ETL/extract_data.py", line 5, in <module>
    import ETL.config as config
  File "/opt/airflow/ETL/config.py", line 8
    CARDS_FILE_LOCAL = os.path.join(DATA_DIR, "cards_data.csv") use to test in local
                                                                ^
SyntaxError: invalid syntax
[2025-06-22T16:16:52.413+0000] {processor.py:842} WARNING - No viable dags retrieved from /opt/airflow/dags/etl_cards_dag.py
[2025-06-22T16:16:52.525+0000] {processor.py:183} INFO - Processing /opt/airflow/dags/etl_cards_dag.py took 1.339 seconds
[2025-06-22T16:17:22.692+0000] {processor.py:161} INFO - Started process (PID=2144) to work on /opt/airflow/dags/etl_cards_dag.py
[2025-06-22T16:17:22.696+0000] {processor.py:830} INFO - Processing file /opt/airflow/dags/etl_cards_dag.py for tasks to queue
[2025-06-22T16:17:22.699+0000] {logging_mixin.py:188} INFO - [2025-06-22T16:17:22.698+0000] {dagbag.py:538} INFO - Filling up the DagBag from /opt/airflow/dags/etl_cards_dag.py
[2025-06-22T16:17:23.668+0000] {logging_mixin.py:188} INFO - [2025-06-22T16:17:23.652+0000] {dagbag.py:348} ERROR - Failed to import: /opt/airflow/dags/etl_cards_dag.py
Traceback (most recent call last):
  File "/home/airflow/.local/lib/python3.8/site-packages/airflow/models/dagbag.py", line 344, in parse
    loader.exec_module(new_module)
  File "<frozen importlib._bootstrap_external>", line 843, in exec_module
  File "<frozen importlib._bootstrap>", line 219, in _call_with_frames_removed
  File "/opt/airflow/dags/etl_cards_dag.py", line 13, in <module>
    import ETL.extract_data as extract
  File "/opt/airflow/ETL/extract_data.py", line 5, in <module>
    import ETL.config as config
  File "/opt/airflow/ETL/config.py", line 8
    CARDS_FILE_LOCAL = os.path.join(DATA_DIR, "cards_data.csv") use to test in local
                                                                ^
SyntaxError: invalid syntax
[2025-06-22T16:17:23.674+0000] {processor.py:842} WARNING - No viable dags retrieved from /opt/airflow/dags/etl_cards_dag.py
[2025-06-22T16:17:23.774+0000] {processor.py:183} INFO - Processing /opt/airflow/dags/etl_cards_dag.py took 1.090 seconds
[2025-06-22T16:17:54.049+0000] {processor.py:161} INFO - Started process (PID=2152) to work on /opt/airflow/dags/etl_cards_dag.py
[2025-06-22T16:17:54.052+0000] {processor.py:830} INFO - Processing file /opt/airflow/dags/etl_cards_dag.py for tasks to queue
[2025-06-22T16:17:54.056+0000] {logging_mixin.py:188} INFO - [2025-06-22T16:17:54.055+0000] {dagbag.py:538} INFO - Filling up the DagBag from /opt/airflow/dags/etl_cards_dag.py
[2025-06-22T16:17:55.106+0000] {logging_mixin.py:188} INFO - [2025-06-22T16:17:55.088+0000] {dagbag.py:348} ERROR - Failed to import: /opt/airflow/dags/etl_cards_dag.py
Traceback (most recent call last):
  File "/home/airflow/.local/lib/python3.8/site-packages/airflow/models/dagbag.py", line 344, in parse
    loader.exec_module(new_module)
  File "<frozen importlib._bootstrap_external>", line 843, in exec_module
  File "<frozen importlib._bootstrap>", line 219, in _call_with_frames_removed
  File "/opt/airflow/dags/etl_cards_dag.py", line 13, in <module>
    import ETL.extract_data as extract
  File "/opt/airflow/ETL/extract_data.py", line 5, in <module>
    import ETL.config as config
  File "/opt/airflow/ETL/config.py", line 8
    CARDS_FILE_LOCAL = os.path.join(DATA_DIR, "cards_data.csv") use to test in local
                                                                ^
SyntaxError: invalid syntax
[2025-06-22T16:17:55.112+0000] {processor.py:842} WARNING - No viable dags retrieved from /opt/airflow/dags/etl_cards_dag.py
[2025-06-22T16:17:55.159+0000] {processor.py:183} INFO - Processing /opt/airflow/dags/etl_cards_dag.py took 1.118 seconds
[2025-06-22T16:18:25.547+0000] {processor.py:161} INFO - Started process (PID=2160) to work on /opt/airflow/dags/etl_cards_dag.py
[2025-06-22T16:18:25.550+0000] {processor.py:830} INFO - Processing file /opt/airflow/dags/etl_cards_dag.py for tasks to queue
[2025-06-22T16:18:25.554+0000] {logging_mixin.py:188} INFO - [2025-06-22T16:18:25.553+0000] {dagbag.py:538} INFO - Filling up the DagBag from /opt/airflow/dags/etl_cards_dag.py
[2025-06-22T16:18:26.640+0000] {logging_mixin.py:188} INFO - [2025-06-22T16:18:26.620+0000] {dagbag.py:348} ERROR - Failed to import: /opt/airflow/dags/etl_cards_dag.py
Traceback (most recent call last):
  File "/home/airflow/.local/lib/python3.8/site-packages/airflow/models/dagbag.py", line 344, in parse
    loader.exec_module(new_module)
  File "<frozen importlib._bootstrap_external>", line 843, in exec_module
  File "<frozen importlib._bootstrap>", line 219, in _call_with_frames_removed
  File "/opt/airflow/dags/etl_cards_dag.py", line 13, in <module>
    import ETL.extract_data as extract
  File "/opt/airflow/ETL/extract_data.py", line 5, in <module>
    import ETL.config as config
  File "/opt/airflow/ETL/config.py", line 8
    CARDS_FILE_LOCAL = os.path.join(DATA_DIR, "cards_data.csv") use to test in local
                                                                ^
SyntaxError: invalid syntax
[2025-06-22T16:18:26.645+0000] {processor.py:842} WARNING - No viable dags retrieved from /opt/airflow/dags/etl_cards_dag.py
[2025-06-22T16:18:26.691+0000] {processor.py:183} INFO - Processing /opt/airflow/dags/etl_cards_dag.py took 1.154 seconds
[2025-06-22T16:18:56.908+0000] {processor.py:161} INFO - Started process (PID=2168) to work on /opt/airflow/dags/etl_cards_dag.py
[2025-06-22T16:18:56.911+0000] {processor.py:830} INFO - Processing file /opt/airflow/dags/etl_cards_dag.py for tasks to queue
[2025-06-22T16:18:56.914+0000] {logging_mixin.py:188} INFO - [2025-06-22T16:18:56.913+0000] {dagbag.py:538} INFO - Filling up the DagBag from /opt/airflow/dags/etl_cards_dag.py
[2025-06-22T16:18:58.018+0000] {logging_mixin.py:188} INFO - [2025-06-22T16:18:57.999+0000] {dagbag.py:348} ERROR - Failed to import: /opt/airflow/dags/etl_cards_dag.py
Traceback (most recent call last):
  File "/home/airflow/.local/lib/python3.8/site-packages/airflow/models/dagbag.py", line 344, in parse
    loader.exec_module(new_module)
  File "<frozen importlib._bootstrap_external>", line 843, in exec_module
  File "<frozen importlib._bootstrap>", line 219, in _call_with_frames_removed
  File "/opt/airflow/dags/etl_cards_dag.py", line 13, in <module>
    import ETL.extract_data as extract
  File "/opt/airflow/ETL/extract_data.py", line 5, in <module>
    import ETL.config as config
  File "/opt/airflow/ETL/config.py", line 8
    CARDS_FILE_LOCAL = os.path.join(DATA_DIR, "cards_data.csv") use to test in local
                                                                ^
SyntaxError: invalid syntax
[2025-06-22T16:18:58.025+0000] {processor.py:842} WARNING - No viable dags retrieved from /opt/airflow/dags/etl_cards_dag.py
[2025-06-22T16:18:58.124+0000] {processor.py:183} INFO - Processing /opt/airflow/dags/etl_cards_dag.py took 1.224 seconds
[2025-06-22T16:19:28.560+0000] {processor.py:161} INFO - Started process (PID=2176) to work on /opt/airflow/dags/etl_cards_dag.py
[2025-06-22T16:19:28.563+0000] {processor.py:830} INFO - Processing file /opt/airflow/dags/etl_cards_dag.py for tasks to queue
[2025-06-22T16:19:28.567+0000] {logging_mixin.py:188} INFO - [2025-06-22T16:19:28.566+0000] {dagbag.py:538} INFO - Filling up the DagBag from /opt/airflow/dags/etl_cards_dag.py
[2025-06-22T16:19:29.732+0000] {logging_mixin.py:188} INFO - [2025-06-22T16:19:29.714+0000] {dagbag.py:348} ERROR - Failed to import: /opt/airflow/dags/etl_cards_dag.py
Traceback (most recent call last):
  File "/home/airflow/.local/lib/python3.8/site-packages/airflow/models/dagbag.py", line 344, in parse
    loader.exec_module(new_module)
  File "<frozen importlib._bootstrap_external>", line 843, in exec_module
  File "<frozen importlib._bootstrap>", line 219, in _call_with_frames_removed
  File "/opt/airflow/dags/etl_cards_dag.py", line 13, in <module>
    import ETL.extract_data as extract
  File "/opt/airflow/ETL/extract_data.py", line 5, in <module>
    import ETL.config as config
  File "/opt/airflow/ETL/config.py", line 8
    CARDS_FILE_LOCAL = os.path.join(DATA_DIR, "cards_data.csv") use to test in local
                                                                ^
SyntaxError: invalid syntax
[2025-06-22T16:19:29.740+0000] {processor.py:842} WARNING - No viable dags retrieved from /opt/airflow/dags/etl_cards_dag.py
[2025-06-22T16:19:29.788+0000] {processor.py:183} INFO - Processing /opt/airflow/dags/etl_cards_dag.py took 1.235 seconds
[2025-06-22T16:19:59.925+0000] {processor.py:161} INFO - Started process (PID=2184) to work on /opt/airflow/dags/etl_cards_dag.py
[2025-06-22T16:19:59.932+0000] {processor.py:830} INFO - Processing file /opt/airflow/dags/etl_cards_dag.py for tasks to queue
[2025-06-22T16:19:59.935+0000] {logging_mixin.py:188} INFO - [2025-06-22T16:19:59.934+0000] {dagbag.py:538} INFO - Filling up the DagBag from /opt/airflow/dags/etl_cards_dag.py
[2025-06-22T16:20:00.915+0000] {logging_mixin.py:188} INFO - [2025-06-22T16:20:00.899+0000] {dagbag.py:348} ERROR - Failed to import: /opt/airflow/dags/etl_cards_dag.py
Traceback (most recent call last):
  File "/home/airflow/.local/lib/python3.8/site-packages/airflow/models/dagbag.py", line 344, in parse
    loader.exec_module(new_module)
  File "<frozen importlib._bootstrap_external>", line 843, in exec_module
  File "<frozen importlib._bootstrap>", line 219, in _call_with_frames_removed
  File "/opt/airflow/dags/etl_cards_dag.py", line 13, in <module>
    import ETL.extract_data as extract
  File "/opt/airflow/ETL/extract_data.py", line 5, in <module>
    import ETL.config as config
  File "/opt/airflow/ETL/config.py", line 8
    CARDS_FILE_LOCAL = os.path.join(DATA_DIR, "cards_data.csv") use to test in local
                                                                ^
SyntaxError: invalid syntax
[2025-06-22T16:20:00.921+0000] {processor.py:842} WARNING - No viable dags retrieved from /opt/airflow/dags/etl_cards_dag.py
[2025-06-22T16:20:01.021+0000] {processor.py:183} INFO - Processing /opt/airflow/dags/etl_cards_dag.py took 1.103 seconds
[2025-06-22T16:20:31.310+0000] {processor.py:161} INFO - Started process (PID=2192) to work on /opt/airflow/dags/etl_cards_dag.py
[2025-06-22T16:20:31.313+0000] {processor.py:830} INFO - Processing file /opt/airflow/dags/etl_cards_dag.py for tasks to queue
[2025-06-22T16:20:31.318+0000] {logging_mixin.py:188} INFO - [2025-06-22T16:20:31.316+0000] {dagbag.py:538} INFO - Filling up the DagBag from /opt/airflow/dags/etl_cards_dag.py
[2025-06-22T16:20:32.566+0000] {logging_mixin.py:188} INFO - [2025-06-22T16:20:32.547+0000] {dagbag.py:348} ERROR - Failed to import: /opt/airflow/dags/etl_cards_dag.py
Traceback (most recent call last):
  File "/home/airflow/.local/lib/python3.8/site-packages/airflow/models/dagbag.py", line 344, in parse
    loader.exec_module(new_module)
  File "<frozen importlib._bootstrap_external>", line 843, in exec_module
  File "<frozen importlib._bootstrap>", line 219, in _call_with_frames_removed
  File "/opt/airflow/dags/etl_cards_dag.py", line 13, in <module>
    import ETL.extract_data as extract
  File "/opt/airflow/ETL/extract_data.py", line 5, in <module>
    import ETL.config as config
  File "/opt/airflow/ETL/config.py", line 8
    CARDS_FILE_LOCAL = os.path.join(DATA_DIR, "cards_data.csv") use to test in local
                                                                ^
SyntaxError: invalid syntax
[2025-06-22T16:20:32.572+0000] {processor.py:842} WARNING - No viable dags retrieved from /opt/airflow/dags/etl_cards_dag.py
[2025-06-22T16:20:32.618+0000] {processor.py:183} INFO - Processing /opt/airflow/dags/etl_cards_dag.py took 1.318 seconds
[2025-06-22T16:21:02.909+0000] {processor.py:161} INFO - Started process (PID=2200) to work on /opt/airflow/dags/etl_cards_dag.py
[2025-06-22T16:21:02.912+0000] {processor.py:830} INFO - Processing file /opt/airflow/dags/etl_cards_dag.py for tasks to queue
[2025-06-22T16:21:02.915+0000] {logging_mixin.py:188} INFO - [2025-06-22T16:21:02.915+0000] {dagbag.py:538} INFO - Filling up the DagBag from /opt/airflow/dags/etl_cards_dag.py
[2025-06-22T16:21:03.966+0000] {logging_mixin.py:188} INFO - [2025-06-22T16:21:03.947+0000] {dagbag.py:348} ERROR - Failed to import: /opt/airflow/dags/etl_cards_dag.py
Traceback (most recent call last):
  File "/home/airflow/.local/lib/python3.8/site-packages/airflow/models/dagbag.py", line 344, in parse
    loader.exec_module(new_module)
  File "<frozen importlib._bootstrap_external>", line 843, in exec_module
  File "<frozen importlib._bootstrap>", line 219, in _call_with_frames_removed
  File "/opt/airflow/dags/etl_cards_dag.py", line 13, in <module>
    import ETL.extract_data as extract
  File "/opt/airflow/ETL/extract_data.py", line 5, in <module>
    import ETL.config as config
  File "/opt/airflow/ETL/config.py", line 8
    CARDS_FILE_LOCAL = os.path.join(DATA_DIR, "cards_data.csv") use to test in local
                                                                ^
SyntaxError: invalid syntax
[2025-06-22T16:21:03.974+0000] {processor.py:842} WARNING - No viable dags retrieved from /opt/airflow/dags/etl_cards_dag.py
[2025-06-22T16:21:04.028+0000] {processor.py:183} INFO - Processing /opt/airflow/dags/etl_cards_dag.py took 1.129 seconds
[2025-06-22T16:21:34.383+0000] {processor.py:161} INFO - Started process (PID=2208) to work on /opt/airflow/dags/etl_cards_dag.py
[2025-06-22T16:21:34.386+0000] {processor.py:830} INFO - Processing file /opt/airflow/dags/etl_cards_dag.py for tasks to queue
[2025-06-22T16:21:34.389+0000] {logging_mixin.py:188} INFO - [2025-06-22T16:21:34.388+0000] {dagbag.py:538} INFO - Filling up the DagBag from /opt/airflow/dags/etl_cards_dag.py
[2025-06-22T16:21:35.655+0000] {logging_mixin.py:188} INFO - [2025-06-22T16:21:35.609+0000] {dagbag.py:348} ERROR - Failed to import: /opt/airflow/dags/etl_cards_dag.py
Traceback (most recent call last):
  File "/home/airflow/.local/lib/python3.8/site-packages/airflow/models/dagbag.py", line 344, in parse
    loader.exec_module(new_module)
  File "<frozen importlib._bootstrap_external>", line 843, in exec_module
  File "<frozen importlib._bootstrap>", line 219, in _call_with_frames_removed
  File "/opt/airflow/dags/etl_cards_dag.py", line 13, in <module>
    import ETL.extract_data as extract
  File "/opt/airflow/ETL/extract_data.py", line 5, in <module>
    import ETL.config as config
  File "/opt/airflow/ETL/config.py", line 8
    CARDS_FILE_LOCAL = os.path.join(DATA_DIR, "cards_data.csv") use to test in local
                                                                ^
SyntaxError: invalid syntax
[2025-06-22T16:21:35.661+0000] {processor.py:842} WARNING - No viable dags retrieved from /opt/airflow/dags/etl_cards_dag.py
[2025-06-22T16:21:35.763+0000] {processor.py:183} INFO - Processing /opt/airflow/dags/etl_cards_dag.py took 1.386 seconds
[2025-06-22T16:22:06.179+0000] {processor.py:161} INFO - Started process (PID=2216) to work on /opt/airflow/dags/etl_cards_dag.py
[2025-06-22T16:22:06.182+0000] {processor.py:830} INFO - Processing file /opt/airflow/dags/etl_cards_dag.py for tasks to queue
[2025-06-22T16:22:06.185+0000] {logging_mixin.py:188} INFO - [2025-06-22T16:22:06.184+0000] {dagbag.py:538} INFO - Filling up the DagBag from /opt/airflow/dags/etl_cards_dag.py
[2025-06-22T16:22:07.194+0000] {logging_mixin.py:188} INFO - [2025-06-22T16:22:07.177+0000] {dagbag.py:348} ERROR - Failed to import: /opt/airflow/dags/etl_cards_dag.py
Traceback (most recent call last):
  File "/home/airflow/.local/lib/python3.8/site-packages/airflow/models/dagbag.py", line 344, in parse
    loader.exec_module(new_module)
  File "<frozen importlib._bootstrap_external>", line 843, in exec_module
  File "<frozen importlib._bootstrap>", line 219, in _call_with_frames_removed
  File "/opt/airflow/dags/etl_cards_dag.py", line 13, in <module>
    import ETL.extract_data as extract
  File "/opt/airflow/ETL/extract_data.py", line 5, in <module>
    import ETL.config as config
  File "/opt/airflow/ETL/config.py", line 8
    CARDS_FILE_LOCAL = os.path.join(DATA_DIR, "cards_data.csv") use to test in local
                                                                ^
SyntaxError: invalid syntax
[2025-06-22T16:22:07.200+0000] {processor.py:842} WARNING - No viable dags retrieved from /opt/airflow/dags/etl_cards_dag.py
[2025-06-22T16:22:07.253+0000] {processor.py:183} INFO - Processing /opt/airflow/dags/etl_cards_dag.py took 1.082 seconds
[2025-06-22T16:22:37.619+0000] {processor.py:161} INFO - Started process (PID=2224) to work on /opt/airflow/dags/etl_cards_dag.py
[2025-06-22T16:22:37.621+0000] {processor.py:830} INFO - Processing file /opt/airflow/dags/etl_cards_dag.py for tasks to queue
[2025-06-22T16:22:37.624+0000] {logging_mixin.py:188} INFO - [2025-06-22T16:22:37.623+0000] {dagbag.py:538} INFO - Filling up the DagBag from /opt/airflow/dags/etl_cards_dag.py
[2025-06-22T16:22:38.689+0000] {logging_mixin.py:188} INFO - [2025-06-22T16:22:38.671+0000] {dagbag.py:348} ERROR - Failed to import: /opt/airflow/dags/etl_cards_dag.py
Traceback (most recent call last):
  File "/home/airflow/.local/lib/python3.8/site-packages/airflow/models/dagbag.py", line 344, in parse
    loader.exec_module(new_module)
  File "<frozen importlib._bootstrap_external>", line 843, in exec_module
  File "<frozen importlib._bootstrap>", line 219, in _call_with_frames_removed
  File "/opt/airflow/dags/etl_cards_dag.py", line 13, in <module>
    import ETL.extract_data as extract
  File "/opt/airflow/ETL/extract_data.py", line 5, in <module>
    import ETL.config as config
  File "/opt/airflow/ETL/config.py", line 8
    CARDS_FILE_LOCAL = os.path.join(DATA_DIR, "cards_data.csv") use to test in local
                                                                ^
SyntaxError: invalid syntax
[2025-06-22T16:22:38.696+0000] {processor.py:842} WARNING - No viable dags retrieved from /opt/airflow/dags/etl_cards_dag.py
[2025-06-22T16:22:38.739+0000] {processor.py:183} INFO - Processing /opt/airflow/dags/etl_cards_dag.py took 1.129 seconds
[2025-06-22T16:23:08.999+0000] {processor.py:161} INFO - Started process (PID=2232) to work on /opt/airflow/dags/etl_cards_dag.py
[2025-06-22T16:23:09.002+0000] {processor.py:830} INFO - Processing file /opt/airflow/dags/etl_cards_dag.py for tasks to queue
[2025-06-22T16:23:09.005+0000] {logging_mixin.py:188} INFO - [2025-06-22T16:23:09.004+0000] {dagbag.py:538} INFO - Filling up the DagBag from /opt/airflow/dags/etl_cards_dag.py
[2025-06-22T16:23:10.059+0000] {logging_mixin.py:188} INFO - [2025-06-22T16:23:10.042+0000] {dagbag.py:348} ERROR - Failed to import: /opt/airflow/dags/etl_cards_dag.py
Traceback (most recent call last):
  File "/home/airflow/.local/lib/python3.8/site-packages/airflow/models/dagbag.py", line 344, in parse
    loader.exec_module(new_module)
  File "<frozen importlib._bootstrap_external>", line 843, in exec_module
  File "<frozen importlib._bootstrap>", line 219, in _call_with_frames_removed
  File "/opt/airflow/dags/etl_cards_dag.py", line 13, in <module>
    import ETL.extract_data as extract
  File "/opt/airflow/ETL/extract_data.py", line 5, in <module>
    import ETL.config as config
  File "/opt/airflow/ETL/config.py", line 8
    CARDS_FILE_LOCAL = os.path.join(DATA_DIR, "cards_data.csv") use to test in local
                                                                ^
SyntaxError: invalid syntax
[2025-06-22T16:23:10.065+0000] {processor.py:842} WARNING - No viable dags retrieved from /opt/airflow/dags/etl_cards_dag.py
[2025-06-22T16:23:10.113+0000] {processor.py:183} INFO - Processing /opt/airflow/dags/etl_cards_dag.py took 1.123 seconds
[2025-06-22T16:23:40.484+0000] {processor.py:161} INFO - Started process (PID=2240) to work on /opt/airflow/dags/etl_cards_dag.py
[2025-06-22T16:23:40.487+0000] {processor.py:830} INFO - Processing file /opt/airflow/dags/etl_cards_dag.py for tasks to queue
[2025-06-22T16:23:40.491+0000] {logging_mixin.py:188} INFO - [2025-06-22T16:23:40.490+0000] {dagbag.py:538} INFO - Filling up the DagBag from /opt/airflow/dags/etl_cards_dag.py
[2025-06-22T16:23:41.420+0000] {logging_mixin.py:188} INFO - [2025-06-22T16:23:41.404+0000] {dagbag.py:348} ERROR - Failed to import: /opt/airflow/dags/etl_cards_dag.py
Traceback (most recent call last):
  File "/home/airflow/.local/lib/python3.8/site-packages/airflow/models/dagbag.py", line 344, in parse
    loader.exec_module(new_module)
  File "<frozen importlib._bootstrap_external>", line 843, in exec_module
  File "<frozen importlib._bootstrap>", line 219, in _call_with_frames_removed
  File "/opt/airflow/dags/etl_cards_dag.py", line 13, in <module>
    import ETL.extract_data as extract
  File "/opt/airflow/ETL/extract_data.py", line 5, in <module>
    import ETL.config as config
  File "/opt/airflow/ETL/config.py", line 8
    CARDS_FILE_LOCAL = os.path.join(DATA_DIR, "cards_data.csv") use to test in local
                                                                ^
SyntaxError: invalid syntax
[2025-06-22T16:23:41.425+0000] {processor.py:842} WARNING - No viable dags retrieved from /opt/airflow/dags/etl_cards_dag.py
[2025-06-22T16:23:41.528+0000] {processor.py:183} INFO - Processing /opt/airflow/dags/etl_cards_dag.py took 1.050 seconds
[2025-06-22T16:24:11.872+0000] {processor.py:161} INFO - Started process (PID=2248) to work on /opt/airflow/dags/etl_cards_dag.py
[2025-06-22T16:24:11.875+0000] {processor.py:830} INFO - Processing file /opt/airflow/dags/etl_cards_dag.py for tasks to queue
[2025-06-22T16:24:11.878+0000] {logging_mixin.py:188} INFO - [2025-06-22T16:24:11.877+0000] {dagbag.py:538} INFO - Filling up the DagBag from /opt/airflow/dags/etl_cards_dag.py
[2025-06-22T16:24:13.075+0000] {logging_mixin.py:188} INFO - [2025-06-22T16:24:13.057+0000] {dagbag.py:348} ERROR - Failed to import: /opt/airflow/dags/etl_cards_dag.py
Traceback (most recent call last):
  File "/home/airflow/.local/lib/python3.8/site-packages/airflow/models/dagbag.py", line 344, in parse
    loader.exec_module(new_module)
  File "<frozen importlib._bootstrap_external>", line 843, in exec_module
  File "<frozen importlib._bootstrap>", line 219, in _call_with_frames_removed
  File "/opt/airflow/dags/etl_cards_dag.py", line 13, in <module>
    import ETL.extract_data as extract
  File "/opt/airflow/ETL/extract_data.py", line 5, in <module>
    import ETL.config as config
  File "/opt/airflow/ETL/config.py", line 8
    CARDS_FILE_LOCAL = os.path.join(DATA_DIR, "cards_data.csv") use to test in local
                                                                ^
SyntaxError: invalid syntax
[2025-06-22T16:24:13.082+0000] {processor.py:842} WARNING - No viable dags retrieved from /opt/airflow/dags/etl_cards_dag.py
[2025-06-22T16:24:13.136+0000] {processor.py:183} INFO - Processing /opt/airflow/dags/etl_cards_dag.py took 1.275 seconds
[2025-06-22T16:24:43.339+0000] {processor.py:161} INFO - Started process (PID=2256) to work on /opt/airflow/dags/etl_cards_dag.py
[2025-06-22T16:24:43.342+0000] {processor.py:830} INFO - Processing file /opt/airflow/dags/etl_cards_dag.py for tasks to queue
[2025-06-22T16:24:43.345+0000] {logging_mixin.py:188} INFO - [2025-06-22T16:24:43.344+0000] {dagbag.py:538} INFO - Filling up the DagBag from /opt/airflow/dags/etl_cards_dag.py
[2025-06-22T16:24:44.331+0000] {logging_mixin.py:188} INFO - [2025-06-22T16:24:44.313+0000] {dagbag.py:348} ERROR - Failed to import: /opt/airflow/dags/etl_cards_dag.py
Traceback (most recent call last):
  File "/home/airflow/.local/lib/python3.8/site-packages/airflow/models/dagbag.py", line 344, in parse
    loader.exec_module(new_module)
  File "<frozen importlib._bootstrap_external>", line 843, in exec_module
  File "<frozen importlib._bootstrap>", line 219, in _call_with_frames_removed
  File "/opt/airflow/dags/etl_cards_dag.py", line 13, in <module>
    import ETL.extract_data as extract
  File "/opt/airflow/ETL/extract_data.py", line 5, in <module>
    import ETL.config as config
  File "/opt/airflow/ETL/config.py", line 8
    CARDS_FILE_LOCAL = os.path.join(DATA_DIR, "cards_data.csv") use to test in local
                                                                ^
SyntaxError: invalid syntax
[2025-06-22T16:24:44.338+0000] {processor.py:842} WARNING - No viable dags retrieved from /opt/airflow/dags/etl_cards_dag.py
[2025-06-22T16:24:44.428+0000] {processor.py:183} INFO - Processing /opt/airflow/dags/etl_cards_dag.py took 1.096 seconds
[2025-06-22T16:25:14.630+0000] {processor.py:161} INFO - Started process (PID=2264) to work on /opt/airflow/dags/etl_cards_dag.py
[2025-06-22T16:25:14.632+0000] {processor.py:830} INFO - Processing file /opt/airflow/dags/etl_cards_dag.py for tasks to queue
[2025-06-22T16:25:14.635+0000] {logging_mixin.py:188} INFO - [2025-06-22T16:25:14.634+0000] {dagbag.py:538} INFO - Filling up the DagBag from /opt/airflow/dags/etl_cards_dag.py
[2025-06-22T16:25:15.674+0000] {logging_mixin.py:188} INFO - [2025-06-22T16:25:15.656+0000] {dagbag.py:348} ERROR - Failed to import: /opt/airflow/dags/etl_cards_dag.py
Traceback (most recent call last):
  File "/home/airflow/.local/lib/python3.8/site-packages/airflow/models/dagbag.py", line 344, in parse
    loader.exec_module(new_module)
  File "<frozen importlib._bootstrap_external>", line 843, in exec_module
  File "<frozen importlib._bootstrap>", line 219, in _call_with_frames_removed
  File "/opt/airflow/dags/etl_cards_dag.py", line 13, in <module>
    import ETL.extract_data as extract
  File "/opt/airflow/ETL/extract_data.py", line 5, in <module>
    import ETL.config as config
  File "/opt/airflow/ETL/config.py", line 8
    CARDS_FILE_LOCAL = os.path.join(DATA_DIR, "cards_data.csv") use to test in local
                                                                ^
SyntaxError: invalid syntax
[2025-06-22T16:25:15.680+0000] {processor.py:842} WARNING - No viable dags retrieved from /opt/airflow/dags/etl_cards_dag.py
[2025-06-22T16:25:15.724+0000] {processor.py:183} INFO - Processing /opt/airflow/dags/etl_cards_dag.py took 1.102 seconds
[2025-06-22T16:25:46.137+0000] {processor.py:161} INFO - Started process (PID=2272) to work on /opt/airflow/dags/etl_cards_dag.py
[2025-06-22T16:25:46.140+0000] {processor.py:830} INFO - Processing file /opt/airflow/dags/etl_cards_dag.py for tasks to queue
[2025-06-22T16:25:46.142+0000] {logging_mixin.py:188} INFO - [2025-06-22T16:25:46.141+0000] {dagbag.py:538} INFO - Filling up the DagBag from /opt/airflow/dags/etl_cards_dag.py
[2025-06-22T16:25:46.985+0000] {logging_mixin.py:188} INFO - [2025-06-22T16:25:46.970+0000] {dagbag.py:348} ERROR - Failed to import: /opt/airflow/dags/etl_cards_dag.py
Traceback (most recent call last):
  File "/home/airflow/.local/lib/python3.8/site-packages/airflow/models/dagbag.py", line 344, in parse
    loader.exec_module(new_module)
  File "<frozen importlib._bootstrap_external>", line 843, in exec_module
  File "<frozen importlib._bootstrap>", line 219, in _call_with_frames_removed
  File "/opt/airflow/dags/etl_cards_dag.py", line 13, in <module>
    import ETL.extract_data as extract
  File "/opt/airflow/ETL/extract_data.py", line 5, in <module>
    import ETL.config as config
  File "/opt/airflow/ETL/config.py", line 8
    CARDS_FILE_LOCAL = os.path.join(DATA_DIR, "cards_data.csv") use to test in local
                                                                ^
SyntaxError: invalid syntax
[2025-06-22T16:25:46.990+0000] {processor.py:842} WARNING - No viable dags retrieved from /opt/airflow/dags/etl_cards_dag.py
[2025-06-22T16:25:47.089+0000] {processor.py:183} INFO - Processing /opt/airflow/dags/etl_cards_dag.py took 0.957 seconds
[2025-06-22T16:26:17.518+0000] {processor.py:161} INFO - Started process (PID=2281) to work on /opt/airflow/dags/etl_cards_dag.py
[2025-06-22T16:26:17.520+0000] {processor.py:830} INFO - Processing file /opt/airflow/dags/etl_cards_dag.py for tasks to queue
[2025-06-22T16:26:17.523+0000] {logging_mixin.py:188} INFO - [2025-06-22T16:26:17.522+0000] {dagbag.py:538} INFO - Filling up the DagBag from /opt/airflow/dags/etl_cards_dag.py
[2025-06-22T16:26:18.702+0000] {logging_mixin.py:188} INFO - [2025-06-22T16:26:18.685+0000] {dagbag.py:348} ERROR - Failed to import: /opt/airflow/dags/etl_cards_dag.py
Traceback (most recent call last):
  File "/home/airflow/.local/lib/python3.8/site-packages/airflow/models/dagbag.py", line 344, in parse
    loader.exec_module(new_module)
  File "<frozen importlib._bootstrap_external>", line 843, in exec_module
  File "<frozen importlib._bootstrap>", line 219, in _call_with_frames_removed
  File "/opt/airflow/dags/etl_cards_dag.py", line 13, in <module>
    import ETL.extract_data as extract
  File "/opt/airflow/ETL/extract_data.py", line 5, in <module>
    import ETL.config as config
  File "/opt/airflow/ETL/config.py", line 8
    CARDS_FILE_LOCAL = os.path.join(DATA_DIR, "cards_data.csv") use to test in local
                                                                ^
SyntaxError: invalid syntax
[2025-06-22T16:26:18.709+0000] {processor.py:842} WARNING - No viable dags retrieved from /opt/airflow/dags/etl_cards_dag.py
[2025-06-22T16:26:18.756+0000] {processor.py:183} INFO - Processing /opt/airflow/dags/etl_cards_dag.py took 1.247 seconds
                                                                                                                                                                                                                                                                                                                                                                                                                                                                                                                                                                                                                                                                                                                                                                                                                                                                                                                                                                                                                                                                                                                                                                                                                                                                                                                                                                                                                                                                                                                                                                                                                                                               