[2025-06-25T11:30:09.124+0000] {taskinstance.py:1956} INFO - Dependencies all met for dep_context=non-requeueable deps ti=<TaskInstance: cards_etl.etl_cards_task scheduled__2025-06-24T00:00:00+00:00 [queued]>
[2025-06-25T11:30:09.149+0000] {taskinstance.py:1956} INFO - Dependencies all met for dep_context=requeueable deps ti=<TaskInstance: cards_etl.etl_cards_task scheduled__2025-06-24T00:00:00+00:00 [queued]>
[2025-06-25T11:30:09.151+0000] {taskinstance.py:2170} INFO - Starting attempt 1 of 2
[2025-06-25T11:30:09.170+0000] {taskinstance.py:2191} INFO - Executing <Task(PythonOperator): etl_cards_task> on 2025-06-24 00:00:00+00:00
[2025-06-25T11:30:09.179+0000] {standard_task_runner.py:60} INFO - Started process 875 to run task
[2025-06-25T11:30:09.182+0000] {standard_task_runner.py:87} INFO - Running: ['***', 'tasks', 'run', 'cards_etl', 'etl_cards_task', 'scheduled__2025-06-24T00:00:00+00:00', '--job-id', '34', '--raw', '--subdir', 'DAGS_FOLDER/etl_cards_dag.py', '--cfg-path', '/tmp/tmp5nxghj5g']
[2025-06-25T11:30:09.187+0000] {standard_task_runner.py:88} INFO - Job 34: Subtask etl_cards_task
[2025-06-25T11:30:09.264+0000] {task_command.py:423} INFO - Running <TaskInstance: cards_etl.etl_cards_task scheduled__2025-06-24T00:00:00+00:00 [running]> on host 65da94c758f2
[2025-06-25T11:30:10.900+0000] {taskinstance.py:2480} INFO - Exporting env vars: AIRFLOW_CTX_DAG_OWNER='jimmy' AIRFLOW_CTX_DAG_ID='cards_etl' AIRFLOW_CTX_TASK_ID='etl_cards_task' AIRFLOW_CTX_EXECUTION_DATE='2025-06-24T00:00:00+00:00' AIRFLOW_CTX_TRY_NUMBER='1' AIRFLOW_CTX_DAG_RUN_ID='scheduled__2025-06-24T00:00:00+00:00'
[2025-06-25T11:30:10.902+0000] {etl_cards_dag.py:21} INFO - Starting ETL for cards
[2025-06-25T11:30:11.083+0000] {extract_data.py:22} INFO - âœ… Extracted cards_data.csv with 6146 records
[2025-06-25T11:30:11.116+0000] {transform_cards.py:71} INFO - Removed columns ['client_id', 'card_number', 'cvv'] from CARDS data.
[2025-06-25T11:30:11.142+0000] {warnings.py:109} WARNING - /opt/***/ETL/transform_cards.py:88: UserWarning: Could not infer format, so each element will be parsed individually, falling back to `dateutil`. To ensure parsing is consistent and as-expected, please specify a format.
  df['expires'] = pd.to_datetime(df['expires'], errors='coerce')

[2025-06-25T11:30:11.160+0000] {transform_cards.py:89} INFO - Set data types for CARDS data.
[2025-06-25T11:30:11.196+0000] {load_data.py:34} INFO - Successfully created database connection engine.
[2025-06-25T11:30:11.994+0000] {load_data.py:83} ERROR - Error loading data into table 'dim_card': (pyodbc.ProgrammingError) ('42000', '[42000] [Microsoft][ODBC Driver 18 for SQL Server][SQL Server]Cannot open database "FinancialDW" requested by the login. The login failed. (4060) (SQLDriverConnect)')
(Background on this error at: https://sqlalche.me/e/14/f405)
[2025-06-25T11:30:11.995+0000] {taskinstance.py:2698} ERROR - Task failed with exception
Traceback (most recent call last):
  File "/home/airflow/.local/lib/python3.8/site-packages/sqlalchemy/engine/base.py", line 3371, in _wrap_pool_connect
    return fn()
  File "/home/airflow/.local/lib/python3.8/site-packages/sqlalchemy/pool/base.py", line 327, in connect
    return _ConnectionFairy._checkout(self)
  File "/home/airflow/.local/lib/python3.8/site-packages/sqlalchemy/pool/base.py", line 894, in _checkout
    fairy = _ConnectionRecord.checkout(pool)
  File "/home/airflow/.local/lib/python3.8/site-packages/sqlalchemy/pool/base.py", line 493, in checkout
    rec = pool._do_get()
  File "/home/airflow/.local/lib/python3.8/site-packages/sqlalchemy/pool/impl.py", line 146, in _do_get
    self._dec_overflow()
  File "/home/airflow/.local/lib/python3.8/site-packages/sqlalchemy/util/langhelpers.py", line 70, in __exit__
    compat.raise_(
  File "/home/airflow/.local/lib/python3.8/site-packages/sqlalchemy/util/compat.py", line 211, in raise_
    raise exception
  File "/home/airflow/.local/lib/python3.8/site-packages/sqlalchemy/pool/impl.py", line 143, in _do_get
    return self._create_connection()
  File "/home/airflow/.local/lib/python3.8/site-packages/sqlalchemy/pool/base.py", line 273, in _create_connection
    return _ConnectionRecord(self)
  File "/home/airflow/.local/lib/python3.8/site-packages/sqlalchemy/pool/base.py", line 388, in __init__
    self.__connect()
  File "/home/airflow/.local/lib/python3.8/site-packages/sqlalchemy/pool/base.py", line 691, in __connect
    pool.logger.debug("Error on connect(): %s", e)
  File "/home/airflow/.local/lib/python3.8/site-packages/sqlalchemy/util/langhelpers.py", line 70, in __exit__
    compat.raise_(
  File "/home/airflow/.local/lib/python3.8/site-packages/sqlalchemy/util/compat.py", line 211, in raise_
    raise exception
  File "/home/airflow/.local/lib/python3.8/site-packages/sqlalchemy/pool/base.py", line 686, in __connect
    self.dbapi_connection = connection = pool._invoke_creator(self)
  File "/home/airflow/.local/lib/python3.8/site-packages/sqlalchemy/engine/create.py", line 574, in connect
    return dialect.connect(*cargs, **cparams)
  File "/home/airflow/.local/lib/python3.8/site-packages/sqlalchemy/engine/default.py", line 598, in connect
    return self.dbapi.connect(*cargs, **cparams)
pyodbc.ProgrammingError: ('42000', '[42000] [Microsoft][ODBC Driver 18 for SQL Server][SQL Server]Cannot open database "FinancialDW" requested by the login. The login failed. (4060) (SQLDriverConnect)')

The above exception was the direct cause of the following exception:

Traceback (most recent call last):
  File "/home/airflow/.local/lib/python3.8/site-packages/airflow/models/taskinstance.py", line 433, in _execute_task
    result = execute_callable(context=context, **execute_callable_kwargs)
  File "/home/airflow/.local/lib/python3.8/site-packages/airflow/operators/python.py", line 199, in execute
    return_value = self.execute_callable()
  File "/home/airflow/.local/lib/python3.8/site-packages/airflow/operators/python.py", line 216, in execute_callable
    return self.python_callable(*self.op_args, **self.op_kwargs)
  File "/opt/airflow/dags/etl_cards_dag.py", line 26, in my_etl_task
    load.load_dataframe_to_sql(cards_df_clean2,'dim_card',engine,'financial')
  File "/opt/airflow/ETL/load_data.py", line 73, in load_dataframe_to_sql
    df.to_sql(
  File "/home/airflow/.local/lib/python3.8/site-packages/pandas/core/generic.py", line 2878, in to_sql
    return sql.to_sql(
  File "/home/airflow/.local/lib/python3.8/site-packages/pandas/io/sql.py", line 768, in to_sql
    with pandasSQL_builder(con, schema=schema, need_transaction=True) as pandas_sql:
  File "/home/airflow/.local/lib/python3.8/site-packages/pandas/io/sql.py", line 832, in pandasSQL_builder
    return SQLDatabase(con, schema, need_transaction)
  File "/home/airflow/.local/lib/python3.8/site-packages/pandas/io/sql.py", line 1539, in __init__
    con = self.exit_stack.enter_context(con.connect())
  File "/home/airflow/.local/lib/python3.8/site-packages/sqlalchemy/engine/base.py", line 3325, in connect
    return self._connection_cls(self, close_with_result=close_with_result)
  File "/home/airflow/.local/lib/python3.8/site-packages/sqlalchemy/engine/base.py", line 96, in __init__
    else engine.raw_connection()
  File "/home/airflow/.local/lib/python3.8/site-packages/sqlalchemy/engine/base.py", line 3404, in raw_connection
    return self._wrap_pool_connect(self.pool.connect, _connection)
  File "/home/airflow/.local/lib/python3.8/site-packages/sqlalchemy/engine/base.py", line 3374, in _wrap_pool_connect
    Connection._handle_dbapi_exception_noconnection(
  File "/home/airflow/.local/lib/python3.8/site-packages/sqlalchemy/engine/base.py", line 2208, in _handle_dbapi_exception_noconnection
    util.raise_(
  File "/home/airflow/.local/lib/python3.8/site-packages/sqlalchemy/util/compat.py", line 211, in raise_
    raise exception
  File "/home/airflow/.local/lib/python3.8/site-packages/sqlalchemy/engine/base.py", line 3371, in _wrap_pool_connect
    return fn()
  File "/home/airflow/.local/lib/python3.8/site-packages/sqlalchemy/pool/base.py", line 327, in connect
    return _ConnectionFairy._checkout(self)
  File "/home/airflow/.local/lib/python3.8/site-packages/sqlalchemy/pool/base.py", line 894, in _checkout
    fairy = _ConnectionRecord.checkout(pool)
  File "/home/airflow/.local/lib/python3.8/site-packages/sqlalchemy/pool/base.py", line 493, in checkout
    rec = pool._do_get()
  File "/home/airflow/.local/lib/python3.8/site-packages/sqlalchemy/pool/impl.py", line 146, in _do_get
    self._dec_overflow()
  File "/home/airflow/.local/lib/python3.8/site-packages/sqlalchemy/util/langhelpers.py", line 70, in __exit__
    compat.raise_(
  File "/home/airflow/.local/lib/python3.8/site-packages/sqlalchemy/util/compat.py", line 211, in raise_
    raise exception
  File "/home/airflow/.local/lib/python3.8/site-packages/sqlalchemy/pool/impl.py", line 143, in _do_get
    return self._create_connection()
  File "/home/airflow/.local/lib/python3.8/site-packages/sqlalchemy/pool/base.py", line 273, in _create_connection
    return _ConnectionRecord(self)
  File "/home/airflow/.local/lib/python3.8/site-packages/sqlalchemy/pool/base.py", line 388, in __init__
    self.__connect()
  File "/home/airflow/.local/lib/python3.8/site-packages/sqlalchemy/pool/base.py", line 691, in __connect
    pool.logger.debug("Error on connect(): %s", e)
  File "/home/airflow/.local/lib/python3.8/site-packages/sqlalchemy/util/langhelpers.py", line 70, in __exit__
    compat.raise_(
  File "/home/airflow/.local/lib/python3.8/site-packages/sqlalchemy/util/compat.py", line 211, in raise_
    raise exception
  File "/home/airflow/.local/lib/python3.8/site-packages/sqlalchemy/pool/base.py", line 686, in __connect
    self.dbapi_connection = connection = pool._invoke_creator(self)
  File "/home/airflow/.local/lib/python3.8/site-packages/sqlalchemy/engine/create.py", line 574, in connect
    return dialect.connect(*cargs, **cparams)
  File "/home/airflow/.local/lib/python3.8/site-packages/sqlalchemy/engine/default.py", line 598, in connect
    return self.dbapi.connect(*cargs, **cparams)
sqlalchemy.exc.ProgrammingError: (pyodbc.ProgrammingError) ('42000', '[42000] [Microsoft][ODBC Driver 18 for SQL Server][SQL Server]Cannot open database "FinancialDW" requested by the login. The login failed. (4060) (SQLDriverConnect)')
(Background on this error at: https://sqlalche.me/e/14/f405)
[2025-06-25T11:30:12.098+0000] {taskinstance.py:1138} INFO - Marking task as UP_FOR_RETRY. dag_id=cards_etl, task_id=etl_cards_task, execution_date=20250624T000000, start_date=20250625T113009, end_date=20250625T113012
[2025-06-25T11:30:12.153+0000] {standard_task_runner.py:107} ERROR - Failed to execute job 34 for task etl_cards_task ((pyodbc.ProgrammingError) ('42000', '[42000] [Microsoft][ODBC Driver 18 for SQL Server][SQL Server]Cannot open database "FinancialDW" requested by the login. The login failed. (4060) (SQLDriverConnect)')
(Background on this error at: https://sqlalche.me/e/14/f405); 875)
[2025-06-25T11:30:12.222+0000] {local_task_job_runner.py:234} INFO - Task exited with return code 1
[2025-06-25T11:30:12.245+0000] {taskinstance.py:3280} INFO - 0 downstream tasks scheduled from follow-on schedule check
