[2025-06-26T12:11:14.113+0000] {taskinstance.py:1956} INFO - Dependencies all met for dep_context=non-requeueable deps ti=<TaskInstance: cards_etl.etl_cards_task manual__2025-06-26T12:10:43.278674+00:00 [queued]>
[2025-06-26T12:11:14.133+0000] {taskinstance.py:1956} INFO - Dependencies all met for dep_context=requeueable deps ti=<TaskInstance: cards_etl.etl_cards_task manual__2025-06-26T12:10:43.278674+00:00 [queued]>
[2025-06-26T12:11:14.134+0000] {taskinstance.py:2170} INFO - Starting attempt 2 of 2
[2025-06-26T12:11:14.165+0000] {taskinstance.py:2191} INFO - Executing <Task(PythonOperator): etl_cards_task> on 2025-06-26 12:10:43.278674+00:00
[2025-06-26T12:11:14.179+0000] {standard_task_runner.py:60} INFO - Started process 3171 to run task
[2025-06-26T12:11:14.184+0000] {standard_task_runner.py:87} INFO - Running: ['***', 'tasks', 'run', 'cards_etl', 'etl_cards_task', 'manual__2025-06-26T12:10:43.278674+00:00', '--job-id', '41', '--raw', '--subdir', 'DAGS_FOLDER/etl_cards_dag.py', '--cfg-path', '/tmp/tmp_o0ncxu_']
[2025-06-26T12:11:14.189+0000] {standard_task_runner.py:88} INFO - Job 41: Subtask etl_cards_task
[2025-06-26T12:11:14.283+0000] {task_command.py:423} INFO - Running <TaskInstance: cards_etl.etl_cards_task manual__2025-06-26T12:10:43.278674+00:00 [running]> on host 65da94c758f2
[2025-06-26T12:11:14.903+0000] {taskinstance.py:2480} INFO - Exporting env vars: AIRFLOW_CTX_DAG_OWNER='jimmy' AIRFLOW_CTX_DAG_ID='cards_etl' AIRFLOW_CTX_TASK_ID='etl_cards_task' AIRFLOW_CTX_EXECUTION_DATE='2025-06-26T12:10:43.278674+00:00' AIRFLOW_CTX_TRY_NUMBER='2' AIRFLOW_CTX_DAG_RUN_ID='manual__2025-06-26T12:10:43.278674+00:00'
[2025-06-26T12:11:14.905+0000] {etl_cards_dag.py:22} INFO - Starting ETL for cards
[2025-06-26T12:11:14.980+0000] {extract_data.py:22} INFO - âœ… Extracted cards_data.csv with 6146 records
[2025-06-26T12:11:15.022+0000] {ETL_dim_card.py:51} ERROR - An error occurred while transforming CARDS data: 'card_id'
[2025-06-26T12:11:15.024+0000] {taskinstance.py:2698} ERROR - Task failed with exception
Traceback (most recent call last):
  File "/home/airflow/.local/lib/python3.8/site-packages/pandas/core/indexes/base.py", line 3653, in get_loc
    return self._engine.get_loc(casted_key)
  File "pandas/_libs/index.pyx", line 147, in pandas._libs.index.IndexEngine.get_loc
  File "pandas/_libs/index.pyx", line 176, in pandas._libs.index.IndexEngine.get_loc
  File "pandas/_libs/hashtable_class_helper.pxi", line 7080, in pandas._libs.hashtable.PyObjectHashTable.get_item
  File "pandas/_libs/hashtable_class_helper.pxi", line 7088, in pandas._libs.hashtable.PyObjectHashTable.get_item
KeyError: 'card_id'

The above exception was the direct cause of the following exception:

Traceback (most recent call last):
  File "/home/airflow/.local/lib/python3.8/site-packages/airflow/models/taskinstance.py", line 433, in _execute_task
    result = execute_callable(context=context, **execute_callable_kwargs)
  File "/home/airflow/.local/lib/python3.8/site-packages/airflow/operators/python.py", line 199, in execute
    return_value = self.execute_callable()
  File "/home/airflow/.local/lib/python3.8/site-packages/airflow/operators/python.py", line 216, in execute_callable
    return self.python_callable(*self.op_args, **self.op_kwargs)
  File "/opt/airflow/dags/etl_cards_dag.py", line 24, in my_etl_task
    cards_df_clean = etl_dim_card.cards_transform(cards_df)
  File "/opt/airflow/ETL/ETL_dim_card.py", line 43, in cards_transform
    df_cleaned['card_id'] = df['card_id'].astype(str)
  File "/home/airflow/.local/lib/python3.8/site-packages/pandas/core/frame.py", line 3761, in __getitem__
    indexer = self.columns.get_loc(key)
  File "/home/airflow/.local/lib/python3.8/site-packages/pandas/core/indexes/base.py", line 3655, in get_loc
    raise KeyError(key) from err
KeyError: 'card_id'
[2025-06-26T12:11:15.073+0000] {taskinstance.py:1138} INFO - Marking task as FAILED. dag_id=cards_etl, task_id=etl_cards_task, execution_date=20250626T121043, start_date=20250626T121114, end_date=20250626T121115
[2025-06-26T12:11:15.100+0000] {standard_task_runner.py:107} ERROR - Failed to execute job 41 for task etl_cards_task ('card_id'; 3171)
[2025-06-26T12:11:15.165+0000] {local_task_job_runner.py:234} INFO - Task exited with return code 1
[2025-06-26T12:11:15.199+0000] {taskinstance.py:3280} INFO - 0 downstream tasks scheduled from follow-on schedule check
